Workbook

Sheet Instructions
A1: No. | B1: How to Use TYL Masterdata
A2: 1 | B2: Personal Data of the students must be entered only by FPC of the respective department
A3: 2 | B3: Please enter data in sorted Assessding order of students USN
A4: 3 | B4: Marks of the students can be entered by respective owners or assigned people from HOD
A5: 4 | B5: All Email Id's must be CMRIT Email id's, and USN must be Complete USN not the Roll Numbers
A6: 5 | B6: Enter the marks scored by the students in marks scored column
A7: 6 | B7: Do not enter 0 or 1 in the adacent column of marks scored. It will be automated
A8: 7 | B8: Please enter Max Marks allotted and Passing marks for each exam
A9: 8 | B9: VTU Results coulmn is only for Detained or Drop out studetns. For Regular students leave it blank
B11: Important Notice
A12: 1 | B12: Please do not alter the size of any column
A13: 2 | B13: Please do not Hide or Shrink any columns as others might be using it
A14: 3 | B14: Instead of CTRL+V for Paste use CTRL+SHIFT+V so the format of the Excel wont change
A15: 4 | B15: BLACK COLORED ROW IS TO ENTER THE PASSING MARKS IN THAT PARTICULAR SUBJECT

Sheet L1 
A1: pasa23aiml@cmrit.ac.in | B1: 98
A2: shpa23ainds@cmrit.ac.in | B2: 96
A3: kadhiravan.aids24le@cmrit.ac.in | B3: 96
A4: sunagar.aids24le@cmrit.ac.in | B4: 96
A5: charan.aids24le@cmrit.ac.in | B5: 84
A6: sudeep.aids24le@cmrit.ac.in | B6: 84
A7: kenneth.aids24le@cmrit.ac.in | B7: 84
A8: kiran.ece24le@cmrit.ac.in | B8: 84
A9: ranjithkumar.ece24le@cmrit.ac.in | B9: 80
A10: shreyas.cseds24le@cmrit.ac.in | B10: 80
A11: shma23ise@cmrit.ac.in | B11: 76
A12: gokul.ece24le@cmrit.ac.in | B12: 76
... A108: sukt23ece@cmrit.ac.in | B108: 16

Sheet L2
A1: arr23ainds@cmrit.ac.in | B1: 92
A2: kadhiravan.aids24le@cmrit.ac.in | B2: 92
A3: karankumar.aids24le@cmrit.ac.in | B3: 92
A4: srujan.ise24le@cmrit.ac.in | B4: 92
A5: rinesh.aids24le@cmrit.ac.in | B5: 92
A6: kartikjayavant.ise24le@cmrit.ac.in | B6: 92
A7: twinkletanya.ise24le@cmrit.ac.in | B7: 92
A8: sunagar.aids24le@cmrit.ac.in | B8: 88
A9: amar.ise24le@cmrit.ac.in | B9: 88
A10: bhsh23ainds@cmrit.ac.in | B10: 88
A11: harshavardhan.ise24le@cmrit.ac.in | B11: 88
A12: charan.aids24le@cmrit.ac.in | B12: 88
... A106: vishwanath.cse24le@cmrit.ac.in | B106: 16

Sheet L3
A1: 1CR23CS001 | B1: 70 | C1: =IF(B1>=70,"PASS","FAIL") -> PASS
A2: 1CR23CS002 | B2: 82 | C2: =IF(B2>=70,"PASS","FAIL") -> PASS
A3: 1CR23CS003 | B3: 70 | C3: =IF(B3>=70,"PASS","FAIL") -> PASS
A4: 1CR23CS004 | B4: 49 | C4: =IF(B4>=70,"PASS","FAIL") -> FAIL
A5: 1CR23CS005 | B5: 70 | C5: =IF(B5>=70,"PASS","FAIL") -> PASS
A6: 1CR23CS006 | B6: 54 | C6: =IF(B6>=70,"PASS","FAIL") -> FAIL | D6: Overall pass % across all brances = 43%
A7: 1CR23CS007 | B7: 70 | C7: =IF(B7>=70,"PASS","FAIL") -> PASS
A8: 1CR23CS008 | B8: 70 | C8: =IF(B8>=70,"PASS","FAIL") -> PASS
A9: 1CR23CS009 | B9: 70 | C9: =IF(B9>=70,"PASS","FAIL") -> PASS
A10: 1CR23CS010 | B10: 78 | C10: =IF(B10>=70,"PASS","FAIL") -> PASS
A11: 1CR23CS011 | B11: 6 | C11: =IF(B11>=70,"PASS","FAIL") -> FAIL
A12: 1CR23CS012 | B12: 72 | C12: =IF(B12>=70,"PASS","FAIL") -> PASS
A13: 1CR23CS013 | B13: 21 | C13: =IF(B13>=70,"PASS","FAIL") -> FAIL
A14: 1CR23CS014 | B14: 75 | C14: =IF(B14>=70,"PASS","FAIL") -> PASS
A15: 1CR23CS015 | B15: 71 | C15: =IF(B15>=70,"PASS","FAIL") -> PASS
A16: 1CR23CS016 | B16: 33 | C16: =IF(B16>=70,"PASS","FAIL") -> FAIL
A17: 1CR23CS017 | B17: 70 | C17: =IF(B17>=70,"PASS","FAIL") -> PASS
A18: 1CR23CS018 | B18: 88 | C18: =IF(B18>=70,"PASS","FAIL") -> PASS
... A113: 1CR23CS113 | B113: 77 | C113: =IF(B113>=70,"PASS","FAIL") -> PASS
A114: 1CR23CS114 | B114: 81 | C114: FAIL
A115: 1CR23CS115 | B115: 76 | C115: =IF(B115>=70,"PASS","FAIL") -> PASS
A116: 1CR23CS116 | B116: 82 | C116: =IF(B116>=70,"PASS","FAIL") -> PASS
A117: 1CR23CS117 | B117: 70 | C117: =IF(B117>=70,"PASS","FAIL") -> PASS
A118: 1CR23CS118 | B118: 70 | C118: =IF(B118>=70,"PASS","FAIL") -> PASS
A119: 1CR23CS119 | B119: 79 | C119: =IF(B119>=70,"PASS","FAIL") -> PASS
A120: 1CR23CS120 | B120: 74 | C120: =IF(B120>=70,"PASS","FAIL") -> PASS
A121: 1CR23CS121 | B121: 73 | C121: =IF(B121>=70,"PASS","FAIL") -> PASS
A122: 1CR23CS122 | B122: 70 | C122: =IF(B122>=70,"PASS","FAIL") -> PASS
A123: 1CR23CS123 | B123: 70 | C123: =IF(B123>=70,"PASS","FAIL") -> PASS
A124: 1CR23CS124 | B124: 75 | C124: =IF(B124>=70,"PASS","FAIL") -> PASS
A125: 1CR23CS125 | B125: 47 | C125: =IF(B125>=70,"PASS","FAIL") -> FAIL
A126: 1CR23CS126 | B126: 71 | C126: =IF(B126>=70,"PASS","FAIL") -> PASS
... A1203: 1CR24CI400 | B1203: 36 | C1203: =IF(B1203>=70,"PASS","FAIL") -> FAIL

Sheet L4
A1: 1CR23CS001 | B1: 71
A2: 1CR23CS002 | B2: 73
A3: 1CR23CS003 | B3: 70
A4: 1CR23CS004 | B4: 70
A5: 1CR23CS005 | B5: 70
A6: 1CR23CS006 | B6: 70
A7: 1CR23CS007 | B7: 70
A8: 1CR23CS008 | B8: 70
A9: 1CR23CS009 | B9: 70
A10: 1CR23CS010 | B10: 80
A11: 1CR23CS011 | B11: 70
A12: 1CR23CS012 | B12: 70
... A1202: 1CR24CD400 | B1202: 70

Sheet S1
A1: 1CR23IS001 | B1: 0
A2: 1CR23IS002 | B2: 93
A3: 1CR23IS003 | B3: 80
A4: 1CR23IS004 | B4: 80
A5: 1CR23IS005 | B5: 50
A6: 1CR23IS006 | B6: 82
A7: 1CR23IS007 | B7: 50
A8: 1CR23IS008 | B8: 80
A9: 1CR23IS009 | B9: 81
A10: 1CR23IS010 | B10: 91
A11: 1CR23IS011 | B11: 79
A12: 1CR23IS012 | B12: 79
... A1203: 1CR24EC423 | B1203: 50

Sheet S2
A1: 1CR23CS001 | B1: 50
A2: 1CR23CS002 | B2: 50
A3: 1CR23CS003 | B3: 63
A4: 1CR23CS004 | B4: 63
A5: 1CR23CS005 | B5: 63
A6: 1CR23CS006 | B6: 62
A7: 1CR23CS007 | B7: 50
A8: 1CR23CS008 | B8: 63
A9: 1CR23CS009 | B9: 50
A10: 1CR23CS010 | B10: 68
A11: 1CR23CS011 | B11: 50
A12: 1CR23CS012 | B12: 50
... A37: 1CR23CS037 | B37: 65
A38: 1CR23CS038 | B38: #N/A
A39: 1CR23CS039 | B39: 0
A40: 1CR23CS040 | B40: 50
A41: 1CR23CS041 | B41: 90
A42: 1CR23CS042 | B42: 65
A43: 1CR23CS043 | B43: 90
A44: 1CR23CS044 | B44: 50
A45: 1CR23CS045 | B45: 73
A46: 1CR23CS046 | B46: 66
A47: 1CR23CS047 | B47: 0
A48: 1CR23CS048 | B48: 73
A49: 1CR23CS049 | B49: 50
A50: 1CR23CS050 | B50: 50
... A61: 1CR23CS061 | B61: 90
A62: 1CR23CS062 | B62: #N/A
A63: 1CR23CS063 | B63: 65
A64: 1CR23CS064 | B64: 73
A65: 1CR23CS065 | B65: 65
A66: 1CR23CS066 | B66: 63
A67: 1CR23CS067 | B67: 65
A68: 1CR23CS068 | B68: 90
A69: 1CR23CS069 | B69: 0
A70: 1CR23CS070 | B70: 63
A71: 1CR23CS071 | B71: 65
A72: 1CR23CS072 | B72: 50
A73: 1CR23CS073 | B73: 66
A74: 1CR23CS074 | B74: 65
...

Sheet S3
A1: 1CR23CS001 | B1: 88
A2: 1CR23CS002 | B2: 74
A3: 1CR23CS003 | B3: 90
A4: 1CR23CS004 | B4: 86
A5: 1CR23CS005 | B5: 86
A6: 1CR23CS006 | B6: 50
A7: 1CR23CS007 | B7: 0
A8: 1CR23CS008 | B8: 0
A9: 1CR23CS009 | B9: 50
A10: 1CR23CS010 | B10: 87
A11: 1CR23CS011 | B11: 0
A12: 1CR23CS012 | B12: 74
... A1163: 1CR22AI034 | B1163: 0

Sheet A2 RETEST 4 DEC
A1: USN | B1: A2 FINAL
A2: 1CR22AI034 | B2: 7
A3: 1CR22CD039 | B3: 0
A4: 1CR22CS094 | B4: 13
A5: 1CR22CS116 | B5: 0
A6: 1CR22CS194 | B6: 23
A7: 1CR22CS209 | B7: 15
A8: 1CR22EC082 | B8: 13
A9: 1CR22EC144 | B9: 0
A10: 1CR22IS191 | B10: 0
A11: 1CR23AD001 | B11: 50
A12: 1CR23AD002 | B12: 45
A13: 1CR23AD003 | B13: 22
... A1165: 1CR24IS416 | B1165: 6

Sheet A1 RETEST 5 DEC
A1: USN | B1: FINAL
A2: 1CR22AI034 | B2: 0
A3: 1CR22CD039 | B3: 25
A4: 1CR22CS094 | B4: 0
A5: 1CR22CS116 | B5: 0
A6: 1CR22CS194 | B6: 0
A7: 1CR22CS209 | B7: 0
A8: 1CR22EC082 | B8: 44
A9: 1CR22EC144 | B9: 0
A10: 1CR22IS191 | B10: 54
A11: 1CR23AD001 | B11: 50
A12: 1CR23AD002 | B12: 59
A13: 1CR23AD003 | B13: 50
... A1165: 1CR24IS416 | B1165: 42

Sheet USN
A1: aapr23ise@cmrit.ac.in | B1: 1CR23IS001
A2: aab23ise@cmrit.ac.in | B2: 1CR23IS002
A3: aara23ise@cmrit.ac.in | B3: 1CR23IS003
A4: aasi23ise@cmrit.ac.in | B4: 1CR23IS004
A5: abti23ise@cmrit.ac.in | B5: 1CR23IS005
A6: ahsu23ise@cmrit.ac.in | B6: 1CR23IS007
A7: akpa23ise@cmrit.ac.in | B7: 1CR23IS008
A8: akku23ise@cmrit.ac.in | B8: 1CR23IS009
A9: amsh23ise@cmrit.ac.in | B9: 1CR23IS012
A10: amkr23ise@cmrit.ac.in | B10: 1CR23IS013
A11: anra23ise@cmrit.ac.in | B11: 1CR23IS014
A12: anve23ise@cmrit.ac.in | B12: 1CR23IS015
... A1088: stkh23ece@cmrit.ac.in | B1088: 1CR23EC217

Sheet Sheet27
A1: 1CR23EC001 | B1: 51.5
A2: 1CR23EC002 | B2: 43.5
A3: 1CR23EC003 | B3: 27
A4: 1CR23EC004 | B4: 0
A5: 1CR23EC005 | B5: 4.5
A6: 1CR23EC006 | B6: 6
A7: 1CR23EC007 | B7: 20
A8: 1CR23EC008 | B8: 0
A9: 1CR23EC009 | B9: 14.5
A10: 1CR23EC010 | B10: 9
A11: 1CR23EC011 | B11: 36.5
A12: 1CR23EC012 | B12: 9.5
... A477: 1CR22CS094 | B477: 12.5

Sheet Sheet23
A1: USN | B1: FINAL MARKS
A2: 1CR23CS002 | B2: 60
A3: 1CR23CS005 | B3: 37
A4: 1CR23CS006 | B4: 69
A5: 1CR23CS013 | B5: 33
A6: 1CR23CS015 | B6: 39
A7: 1CR23CS017 | B7: 72
A8: 1CR23CS018 | B8: 72
A9: 1CR23CS019 | B9: 33
A10: 1CR23CS024 | B10: 59
A11: 1CR23CS027 | B11: 78 | I11: `
A12: 1CR23CS028 | B12: 27
A13: 1CR23CS030 | B13: 68
A14: 1CR23CS031 | B14: 44
A15: 1CR23CS032 | B15: 57
A16: 1CR23CS033 | B16: 52
A17: 1CR23CS034 | B17: 62
A18: 1CR23CS036 | B18: 83
A19: 1CR23CS068 | B19: 60
A20: 1CR23CS041 | B20: 64
A21: 1CR23CS043 | B21: 60
A22: 1CR23CS045 | B22: 52
A23: 1CR23CS047 | B23: 20
... A284: 1CR23CD012 | B284: 25

Sheet UG-CSE
B1: Email | C1: Full Name | D1: USN (Keep data in Assending order) | E1: Phone | F1: BRANCH | G1: Comment (Branch change/Detained/Left college etc...) | H1: Language Lx | L1: Aptitude Ax | P1: Softskill Sx | T1: Core Cx | AA1: Programming Px | AK1: Lx | AL1: Ax | AM1: Cx | AN1: Px | AO1: Sx
B2: Cmrit Email id only | C2: As per PAN Card or 10th Mark scard | E2: 10 digits only | H2: L1 | I2: L2 | J2: L3 | K2: L4 | L2: A1 | M2: A2 | N2: A3 | O2: A4 | P2: S1 | Q2: S2 | R2: S3 | S2: S4 | T2: C2 Odd | U2: C2 Full | V2: C3 Odd | W2: C3 Full | X2: C4 Odd | Y2: C4 Full | Z2: C5 Full | AA2: P1-C | AB2: P2-Python | AC2: P3-Python | AD2: P3-Java | AE2: P4-Programming part 1 | AF2: P4-Programming part 2 | AG2: P4-MAD/FSD | AH2: P4-DS | AI2: P2+ Python | AJ2: Interview Readiness Level by T&P(1- 5 Highest) | AK2: Level Reached | AL2: Level Reached | AM2: Level Reached | AN2: Level Reached | AO2: Level Reached
B3: Max Marks | H3: 100 | I3: 100 | J3: 100 | K3: 100 | L3: 100 | M3: 100 | N3: 100 | O3: 100 | P3: 100 | Q3: 100 | R3: 100 | S3: 100 | T3: 25 | U3: 25 | V3: 100 | W3: 100 | X3: 100 | Y3: 100 | Z3: 100 | AA3: 100 | AB3: 100 | AC3: 100 | AD3: 100 | AE3: 100 | AF3: 100 | AG3: 100 | AH3: 100 | AI3: 100
B4: Passing Marks | H4: 65 | I4: 65 | J4: 70 | K4: 70 | L4: 50 | M4: 50 | N4: 50 | O4: 50 | P4: 50 | Q4: 50 | R4: 50 | S4: 50 | T4: 10 | U4: 10 | V4: 50 | W4: 50 | X4: 50 | Y4: 50 | Z4: 50 | AA4: 50 | AB4: 50 | AC4: 60 | AD4: 60 | AE4: 70 | AF4: 70 | AG4: 70 | AH4: 70 | AI4: 50
A5: 1 | B5: avre23cs@cmrit.ac.in | C5: A VENKATA NAVADEEP REDDY | D5: =VLOOKUP(B5,USN!$1:$1088,2,FALSE) -> 1CR23CS001 | E5: 9663561099 | F5: CSE | H5: 72 | I5: 77 | J5: =IFNA(VLOOKUP(D5,'L3'!$1:$2060,2,False),0) -> 70 | K5: =VLOOKUP(D5,'L4'!$1:$2059,2,FALSE) -> 71 | L5: =VLOOKUP(D5,'A1 RETEST 5 DEC'!$1:$2096,2,FALSE) -> 50 | M5: =VLOOKUP(D5,'A2 RETEST 4 DEC'!$1:$2096,2,FALSE) -> 13 | N5: 50 | P5: =IFNA(VLOOKUP(D5,'S1'!$1:$1325,2,False),0) -> 50 | Q5: =IFNA(vlookup(D5,'S2'!A1:B1203,2,False),0) -> 50 | R5: =ifna(vlookup(D5,'S3'!$1:$1311,2,False),0) -> 88 | T5: 17 | U5: 12 | V5: 84 | X5: 80 | AA5: 40 | AB5: 100 | AC5: 96.5 | AD5: 100 | AE5: 70 | AG5: 61 | AK5: =IF(H5>=$H$4, IF(I5>=$I$4, IF(J5>=$J$4, IF(K5>=$K$4, 4, 3), 2), 1), 0) -> 4 | AL5: =IF(L5>=$L$4, IF(M5>=$M$4, IF(N5>=$N$4, IF(O5>=$O$4, 4, 3), 2), 1), 0) -> 1 | AM5: =IF(AND(U5>=$U$4, W5>=$W$4, Y5>=$Y$4, Z5<>"", Z5>=$Z$4), 5, IF(AND(U5>=$U$4, W5>=$W$4, Y5>=$Y$4), 4, IF(AND(U5>=$U$4, W5>=$W$4), 3, IF(AND(T5>=$T$4, U5>=$U$4), 2, 0 ) ) ) ) -> 2 | AN5: =IF(AB5>=$AB$4, IF(OR(AC5>=$AC$4, AD5>=$AD$4), IF(AND(AE5>=$AE$4, AF5>=$AF$4, OR(AG5>=$AG$4, AH5>=$AH$4)), "4", IF(OR(AE5>=$AE$4, AF5>=$AF$4), "3.5", "3")), "2"), "0") -> 3.5 | AO5: =IF(P5>=$P$4, IF(Q5>=$Q$4, IF(R5>=$R$4, IF(S5>=$S$4,4,3), 2), 1), 0) -> 3
A6: 2 | B6: aagu23cs@cmrit.ac.in | C6: AADITYA GUPTA | D6: =VLOOKUP(B6,USN!$1:$1088,2,FALSE) -> 1CR23CS002 | E6: 8527939636 | F6: CSE | H6: 76 | I6: 90 | J6: =IFNA(VLOOKUP(D6,'L3'!$1:$2060,2,False),0) -> 82 | K6: =VLOOKUP(D6,'L4'!$1:$2059,2,FALSE) -> 73 | L6: =VLOOKUP(D6,'A1 RETEST 5 DEC'!$1:$2096,2,FALSE) -> 60 | M6: =VLOOKUP(D6,'A2 RETEST 4 DEC'!$1:$2096,2,FALSE) -> 50 | N6: 50 | P6: =IFNA(VLOOKUP(D6,'S1'!$1:$1325,2,False),0) -> 75 | Q6: =IFNA(vlookup(D6,'S2'!A2:B1204,2,False),0) -> 50 | R6: =ifna(vlookup(D6,'S3'!$1:$1311,2,False),0) -> 74 | T6: 22 | U6: 17 | V6: 64 | W6: 52 | X6: 72 | AA6: 80 | AB6: 96.25 | AC6: 60 | AD6: 18 | AE6: 23 | AG6: 20 | AK6: =IF(H6>=$H$4, IF(I6>=$I$4, IF(J6>=$J$4, IF(K6>=$K$4, 4, 3), 2), 1), 0) -> 4 | AL6: =IF(L6>=$L$4, IF(M6>=$M$4, IF(N6>=$N$4, IF(O6>=$O$4, 4, 3), 2), 1), 0) -> 3 | AM6: =IF(AND(U6>=$U$4, W6>=$W$4, Y6>=$Y$4, Z6<>"", Z6>=$Z$4), 5, IF(AND(U6>=$U$4, W6>=$W$4, Y6>=$Y$4), 4, IF(AND(U6>=$U$4, W6>=$W$4), 3, IF(AND(T6>=$T$4, U6>=$U$4), 2, 0 ) ) ) ) -> 3 | AN6: =IF(AB6>=$AB$4, IF(OR(AC6>=$AC$4, AD6>=$AD$4), IF(AND(AE6>=$AE$4, AF6>=$AF$4, OR(AG6>=$AG$4, AH6>=$AH$4)), "4", IF(OR(AE6>=$AE$4, AF6>=$AF$4), "3.5", "3")), "2"), "0") -> 3 | AO6: =IF(P6>=$P$4, IF(Q6>=$Q$4, IF(R6>=$R$4, IF(S6>=$S$4,4,3), 2), 1), 0) -> 3
A7: 3 | B7: aadgu23cs@cmrit.ac.in | C7: AADITYA GUPTA | D7: =VLOOKUP(B7,USN!$1:$1088,2,FALSE) -> 1CR23CS003 | E7: 9779820000000 | F7: CSE | H7: 81 | I7: 86 | J7: =IFNA(VLOOKUP(D7,'L3'!$1:$2060,2,False),0) -> 70 | K7: =VLOOKUP(D7,'L4'!$1:$2059,2,FALSE) -> 70 | L7: =VLOOKUP(D7,'A1 RETEST 5 DEC'!$1:$2096,2,FALSE) -> 60 | M7: =VLOOKUP(D7,'A2 RETEST 4 DEC'!$1:$2096,2,FALSE) -> 50 | N7: 50 | P7: =IFNA(VLOOKUP(D7,'S1'!$1:$1325,2,False),0) -> 72 | Q7: =IFNA(vlookup(D7,'S2'!A3:B1205,2,False),0) -> 63 | R7: =ifna(vlookup(D7,'S3'!$1:$1311,2,False),0) -> 90 | T7: 20 | U7: 21 | V7: 72 | W7: 24 | X7: 80 | AA7: 94 | AB7: 97.5 | AC7: 75 | AD7: 60 | AE7: 70 | AG7: 88 | AK7: =IF(H7>=$H$4, IF(I7>=$I$4, IF(J7>=$J$4, IF(K7>=$K$4, 4, 3), 2), 1), 0) -> 4 | AL7: =IF(L7>=$L$4, IF(M7>=$M$4, IF(N7>=$N$4, IF(O7>=$O$4, 4, 3), 2), 1), 0) -> 3 | AM7: =IF(AND(U7>=$U$4, W7>=$W$4, Y7>=$Y$4, Z7<>"", Z7>=$Z$4), 5, IF(AND(U7>=$U$4, W7>=$W$4, Y7>=$Y$4), 4, IF(AND(U7>=$U$4, W7>=$W$4), 3, IF(AND(T7>=$T$4, U7>=$U$4), 2, 0 ) ) ) ) -> 2 | AN7: =IF(AB7>=$AB$4, IF(OR(AC7>=$AC$4, AD7>=$AD$4), IF(AND(AE7>=$AE$4, AF7>=$AF$4, OR(AG7>=$AG$4, AH7>=$AH$4)), "4", IF(OR(AE7>=$AE$4, AF7>=$AF$4), "3.5", "3")), "2"), "0") -> 3.5 | AO7: =IF(P7>=$P$4, IF(Q7>=$Q$4, IF(R7>=$R$4, IF(S7>=$S$4,4,3), 2), 1), 0) -> 3
A8: 4 | B8: aagup23cs@cmrit.ac.in | C8: Aakash Gupta | D8: =VLOOKUP(B8,USN!$1:$1088,2,FALSE) -> 1CR23CS004 | E8: 7033933902 | F8: CSE | H8: 78 | I8: 85 | J8: =IFNA(VLOOKUP(D8,'L3'!$1:$2060,2,False),0) -> 49 | K8: =VLOOKUP(D8,'L4'!$1:$2059,2,FALSE) -> 70 | L8: =VLOOKUP(D8,'A1 RETEST 5 DEC'!$1:$2096,2,FALSE) -> 34 | M8: =VLOOKUP(D8,'A2 RETEST 4 DEC'!$1:$2096,2,FALSE) -> 18 | N8: 40 | P8: =IFNA(VLOOKUP(D8,'S1'!$1:$1325,2,False),0) -> 50 | Q8: =IFNA(vlookup(D8,'S2'!A4:B1206,2,False),0) -> 63 | R8: =ifna(vlookup(D8,'S3'!$1:$1311,2,False),0) -> 86 | T8: 20 | U8: 12 | V8: 56 | W8: 32 | X8: 76 | AA8: 0 | AB8: 93.75 | AC8: 22 | AD8: 70 | AE8: 35 | AG8: 26 | AK8: =IF(H8>=$H$4, IF(I8>=$I$4, IF(J8>=$J$4, IF(K8>=$K$4, 4, 3), 2), 1), 0) -> 2 | AL8: =IF(L8>=$L$4, IF(M8>=$M$4, IF(N8>=$N$4, IF(O8>=$O$4, 4, 3), 2), 1), 0) -> 0 | AM8: =IF(AND(U8>=$U$4, W8>=$W$4, Y8>=$Y$4, Z8<>"", Z8>=$Z$4), 5, IF(AND(U8>=$U$4, W8>=$W$4, Y8>=$Y$4), 4, IF(AND(U8>=$U$4, W8>=$W$4), 3, IF(AND(T8>=$T$4, U8>=$U$4), 2, 0 ) ) ) ) -> 2 | AN8: =IF(AB8>=$AB$4, IF(OR(AC8>=$AC$4, AD8>=$AD$4), IF(AND(AE8>=$AE$4, AF8>=$AF$4, OR(AG8>=$AG$4, AH8>=$AH$4)), "4", IF(OR(AE8>=$AE$4, AF8>=$AF$4), "3.5", "3")), "2"), "0") -> 3 | AO8: =IF(P8>=$P$4, IF(Q8>=$Q$4, IF(R8>=$R$4, IF(S8>=$S$4,4,3), 2), 1), 0) -> 3
A9: 5 | B9: aaru23cs@cmrit.ac.in | C9: AARUHI | D9: =VLOOKUP(B9,USN!$1:$1088,2,FALSE) -> 1CR23CS005 | E9: 9508931008 | F9: CSE | H9: 75 | I9: 83 | J9: =IFNA(VLOOKUP(D9,'L3'!$1:$2060,2,False),0) -> 70 | K9: =VLOOKUP(D9,'L4'!$1:$2059,2,FALSE) -> 70 | L9: =VLOOKUP(D9,'A1 RETEST 5 DEC'!$1:$2096,2,FALSE) -> 50 | M9: =VLOOKUP(D9,'A2 RETEST 4 DEC'!$1:$2096,2,FALSE) -> 50 | N9: 51 | P9: =IFNA(VLOOKUP(D9,'S1'!$1:$1325,2,False),0) -> 82 | Q9: =IFNA(vlookup(D9,'S2'!A5:B1207,2,False),0) -> 63 | R9: =ifna(vlookup(D9,'S3'!$1:$1311,2,False),0) -> 86 | T9: 12 | U9: 21 | V9: 72 | W9: 32 | X9: 80 | AA9: 94 | AB9: 97.5 | AC9: 80 | AD9: 60 | AE9: 70 | AG9: 86 | AK9: =IF(H9>=$H$4, IF(I9>=$I$4, IF(J9>=$J$4, IF(K9>=$K$4, 4, 3), 2), 1), 0) -> 4 | AL9: =IF(L9>=$L$4, IF(M9>=$M$4, IF(N9>=$N$4, IF(O9>=$O$4, 4, 3), 2), 1), 0) -> 3 | AM9: =IF(AND(U9>=$U$4, W9>=$W$4, Y9>=$Y$4, Z9<>"", Z9>=$Z$4), 5, IF(AND(U9>=$U$4, W9>=$W$4, Y9>=$Y$4), 4, IF(AND(U9>=$U$4, W9>=$W$4), 3, IF(AND(T9>=$T$4, U9>=$U$4), 2, 0 ) ) ) ) -> 2 | AN9: =IF(AB9>=$AB$4, IF(OR(AC9>=$AC$4, AD9>=$AD$4), IF(AND(AE9>=$AE$4, AF9>=$AF$4, OR(AG9>=$AG$4, AH9>=$AH$4)), "4", IF(OR(AE9>=$AE$4, AF9>=$AF$4), "3.5", "3")), "2"), "0") -> 3.5 | AO9: =IF(P9>=$P$4, IF(Q9>=$Q$4, IF(R9>=$R$4, IF(S9>=$S$4,4,3), 2), 1), 0) -> 3
A10: 6 | B10: aaup23cs@cmrit.ac.in | C10: AARYAN UPADHYAY | D10: =VLOOKUP(B10,USN!$1:$1088,2,FALSE) -> 1CR23CS006 | E10: 7624945805 | F10: CSE | H10: 85 | I10: 83 | J10: =IFNA(VLOOKUP(D10,'L3'!$1:$2060,2,False),0) -> 54 | K10: =VLOOKUP(D10,'L4'!$1:$2059,2,FALSE) -> 70 | L10: =VLOOKUP(D10,'A1 RETEST 5 DEC'!$1:$2096,2,FALSE) -> 69 | M10: =VLOOKUP(D10,'A2 RETEST 4 DEC'!$1:$2096,2,FALSE) -> 64 | N10: 50 | P10: =IFNA(VLOOKUP(D10,'S1'!$1:$1325,2,False),0) -> 75 | Q10: =IFNA(vlookup(D10,'S2'!A6:B1208,2,False),0) -> 62 | R10: =ifna(vlookup(D10,'S3'!$1:$1311,2,False),0) -> 50 | T10: 12 | U10: 17 | V10: 95 | W10: 40 | X10: 84 | AA10: 88 | AB10: 100 | AC10: 0 | AD10: 90 | AE10: 70 | AG10: 19 | AK10: =IF(H10>=$H$4, IF(I10>=$I$4, IF(J10>=$J$4, IF(K10>=$K$4, 4, 3), 2), 1), 0) -> 2 | AL10: =IF(L10>=$L$4, IF(M10>=$M$4, IF(N10>=$N$4, IF(O10>=$O$4, 4, 3), 2), 1), 0) -> 3 | AM10: =IF(AND(U10>=$U$4, W10>=$W$4, Y10>=$Y$4, Z10<>"", Z10>=$Z$4), 5, IF(AND(U10>=$U$4, W10>=$W$4, Y10>=$Y$4), 4, IF(AND(U10>=$U$4, W10>=$W$4), 3, IF(AND(T10>=$T$4, U10>=$U$4), 2, 0 ) ) ) ) -> 2 | AN10: =IF(AB10>=$AB$4, IF(OR(AC10>=$AC$4, AD10>=$AD$4), IF(AND(AE10>=$AE$4, AF10>=$AF$4, OR(AG10>=$AG$4, AH10>=$AH$4)), "4", IF(OR(AE10>=$AE$4, AF10>=$AF$4), "3.5", "3")), "2"), "0") -> 3.5 | AO10: =IF(P10>=$P$4, IF(Q10>=$Q$4, IF(R10>=$R$4, IF(S10>=$S$4,4,3), 2), 1), 0) -> 3
A11: 7 | B11: aaku23cs@cmrit.ac.in | C11: AASISH KUMAR SAH | D11: =VLOOKUP(B11,USN!$1:$1088,2,FALSE) -> 1CR23CS007 | E11: 9955584833 | F11: CSE | H11: 75 | I11: 70 | J11: =IFNA(VLOOKUP(D11,'L3'!$1:$2060,2,False),0) -> 70 | K11: =VLOOKUP(D11,'L4'!$1:$2059,2,FALSE) -> 70 | L11: =VLOOKUP(D11,'A1 RETEST 5 DEC'!$1:$2096,2,FALSE) -> 12 | M11: =VLOOKUP(D11,'A2 RETEST 4 DEC'!$1:$2096,2,FALSE) -> 35 | N11: 45 | P11: =IFNA(VLOOKUP(D11,'S1'!$1:$1325,2,False),0) -> 0 | Q11: =IFNA(vlookup(D11,'S2'!A7:B1209,2,False),0) -> 50 | R11: =ifna(vlookup(D11,'S3'!$1:$1311,2,False),0) -> 0 | T11: 18 | U11: 22 | V11: 84 | W11: 40 | X11: 86 | AA11: 79.6 | AB11: 78 | AC11: 70.5 | AD11: 60 | AE11: 73 | AG11: 48 | AK11: =IF(H11>=$H$4, IF(I11>=$I$4, IF(J11>=$J$4, IF(K11>=$K$4, 4, 3), 2), 1), 0) -> 4 | AL11: =IF(L11>=$L$4, IF(M11>=$M$4, IF(N11>=$N$4, IF(O11>=$O$4, 4, 3), 2), 1), 0) -> 0 | AM11: =IF(AND(U11>=$U$4, W11>=$W$4, Y11>=$Y$4, Z11<>"", Z11>=$Z$4), 5, IF(AND(U11>=$U$4, W11>=$W$4, Y11>=$Y$4), 4, IF(AND(U11>=$U$4, W11>=$W$4), 3, IF(AND(T11>=$T$4, U11>=$U$4), 2, 0 ) ) ) ) -> 2 | AN11: =IF(AB11>=$AB$4, IF(OR(AC11>=$AC$4, AD11>=$AD$4), IF(AND(AE11>=$AE$4, AF11>=$AF$4, OR(AG11>=$AG$4, AH11>=$AH$4)), "4", IF(OR(AE11>=$AE$4, AF11>=$AF$4), "3.5", "3")), "2"), "0") -> 3.5 | AO11: =IF(P11>=$P$4, IF(Q11>=$Q$4, IF(R11>=$R$4, IF(S11>=$S$4,4,3), 2), 1), 0) -> 0
A12: 8 | B12: aaoj23cs@cmrit.ac.in | C12: Aastha Ojha | D12: =VLOOKUP(B12,USN!$1:$1088,2,FALSE) -> 1CR23CS008 | E12: 7483247816 | F12: CSE | H12: 85 | I12: 82 | J12: =IFNA(VLOOKUP(D12,'L3'!$1:$2060,2,False),0) -> 70 | K12: =VLOOKUP(D12,'L4'!$1:$2059,2,FALSE) -> 70 | L12: =VLOOKUP(D12,'A1 RETEST 5 DEC'!$1:$2096,2,FALSE) -> 45 | M12: =VLOOKUP(D12,'A2 RETEST 4 DEC'!$1:$2096,2,FALSE) -> 19 | N12: 0 | P12: =IFNA(VLOOKUP(D12,'S1'!$1:$1325,2,False),0) -> 87 | Q12: =IFNA(vlookup(D12,'S2'!A8:B1210,2,False),0) -> 63 | R12: =ifna(vlookup(D12,'S3'!$1:$1311,2,False),0) -> 0 | T12: 19 | U12: 17 | V12: 72 | AA12: 15 | AB12: 98.75 | AC12: 82.5 | AD12: 60 | AE12: 10 | AG12: 5 | AK12: =IF(H12>=$H$4, IF(I12>=$I$4, IF(J12>=$J$4, IF(K12>=$K$4, 4, 3), 2), 1), 0) -> 4 | AL12: =IF(L12>=$L$4, IF(M12>=$M$4, IF(N12>=$N$4, IF(O12>=$O$4, 4, 3), 2), 1), 0) -> 0 | AM12: =IF(AND(U12>=$U$4, W12>=$W$4, Y12>=$Y$4, Z12<>"", Z12>=$Z$4), 5, IF(AND(U12>=$U$4, W12>=$W$4, Y12>=$Y$4), 4, IF(AND(U12>=$U$4, W12>=$W$4), 3, IF(AND(T12>=$T$4, U12>=$U$4), 2, 0 ) ) ) ) -> 2 | AN12: =IF(AB12>=$AB$4, IF(OR(AC12>=$AC$4, AD12>=$AD$4), IF(AND(AE12>=$AE$4, AF12>=$AF$4, OR(AG12>=$AG$4, AH12>=$AH$4)), "4", IF(OR(AE12>=$AE$4, AF12>=$AF$4), "3.5", "3")), "2"), "0") -> 3 | AO12: =IF(P12>=$P$4, IF(Q12>=$Q$4, IF(R12>=$R$4, IF(S12>=$S$4,4,3), 2), 1), 0) -> 2
A13: 9 | B13: aach23cs@cmrit.ac.in | C13: Aayush Chaudhary | D13: =VLOOKUP(B13,USN!$1:$1088,2,FALSE) -> 1CR23CS009 | E13: 9811541341 | F13: CSE | H13: 75 | I13: 83 | J13: =IFNA(VLOOKUP(D13,'L3'!$1:$2060,2,False),0) -> 70 | K13: =VLOOKUP(D13,'L4'!$1:$2059,2,FALSE) -> 70 | L13: =VLOOKUP(D13,'A1 RETEST 5 DEC'!$1:$2096,2,FALSE) -> 50 | M13: =VLOOKUP(D13,'A2 RETEST 4 DEC'!$1:$2096,2,FALSE) -> 50 | N13: 50 | P13: =IFNA(VLOOKUP(D13,'S1'!$1:$1325,2,False),0) -> 50 | Q13: =IFNA(vlookup(D13,'S2'!A9:B1211,2,False),0) -> 50 | R13: =ifna(vlookup(D13,'S3'!$1:$1311,2,False),0) -> 50 | T13: 18 | U13: 19 | V13: 84 | W13: 40 | X13: 84 | AA13: 83.2 | AB13: 50 | AC13: 80.5 | AD13: 60 | AE13: 82 | AG13: 76 | AK13: =IF(H13>=$H$4, IF(I13>=$I$4, IF(J13>=$J$4, IF(K13>=$K$4, 4, 3), 2), 1), 0) -> 4 | AL13: =IF(L13>=$L$4, IF(M13>=$M$4, IF(N13>=$N$4, IF(O13>=$O$4, 4, 3), 2), 1), 0) -> 3 | AM13: =IF(AND(U13>=$U$4, W13>=$W$4, Y13>=$Y$4, Z13<>"", Z13>=$Z$4), 5, IF(AND(U13>=$U$4, W13>=$W$4, Y13>=$Y$4), 4, IF(AND(U13>=$U$4, W13>=$W$4), 3, IF(AND(T13>=$T$4, U13>=$U$4), 2, 0 ) ) ) ) -> 2 | AN13: =IF(AB13>=$AB$4, IF(OR(AC13>=$AC$4, AD13>=$AD$4), IF(AND(AE13>=$AE$4, AF13>=$AF$4, OR(AG13>=$AG$4, AH13>=$AH$4)), "4", IF(OR(AE13>=$AE$4, AF13>=$AF$4), "3.5", "3")), "2"), "0") -> 3.5 | AO13: =IF(P13>=$P$4, IF(Q13>=$Q$4, IF(R13>=$R$4, IF(S13>=$S$4,4,3), 2), 1), 0) -> 3
A14: 10 | B14: abba23cs@cmrit.ac.in | C14: Abhisekh Baniya | D14: =VLOOKUP(B14,USN!$1:$1088,2,FALSE) -> 1CR23CS010 | E14: 9766869640 | F14: CSE | H14: 85 | I14: 84 | J14: =IFNA(VLOOKUP(D14,'L3'!$1:$2060,2,False),0) -> 78 | K14: =VLOOKUP(D14,'L4'!$1:$2059,2,FALSE) -> 80 | L14: =VLOOKUP(D14,'A1 RETEST 5 DEC'!$1:$2096,2,FALSE) -> 70 | M14: =VLOOKUP(D14,'A2 RETEST 4 DEC'!$1:$2096,2,FALSE) -> 50 | N14: 56 | P14: =IFNA(VLOOKUP(D14,'S1'!$1:$1325,2,False),0) -> 50 | Q14: =IFNA(vlookup(D14,'S2'!A10:B1212,2,False),0) -> 68 | R14: =ifna(vlookup(D14,'S3'!$1:$1311,2,False),0) -> 87 | T14: 20 | U14: 22 | V14: 72 | W14: 36 | X14: 86 | AA14: 100 | AB14: 100 | AC14: 99 | AD14: 100 | AE14: 70 | AG14: 70 | AK14: =IF(H14>=$H$4, IF(I14>=$I$4, IF(J14>=$J$4, IF(K14>=$K$4, 4, 3), 2), 1), 0) -> 4 | AL14: =IF(L14>=$L$4, IF(M14>=$M$4, IF(N14>=$N$4, IF(O14>=$O$4, 4, 3), 2), 1), 0) -> 3 | AM14: =IF(AND(U14>=$U$4, W14>=$W$4, Y14>=$Y$4, Z14<>"", Z14>=$Z$4), 5, IF(AND(U14>=$U$4, W14>=$W$4, Y14>=$Y$4), 4, IF(AND(U14>=$U$4, W14>=$W$4), 3, IF(AND(T14>=$T$4, U14>=$U$4), 2, 0 ) ) ) ) -> 2 | AN14: =IF(AB14>=$AB$4, IF(OR(AC14>=$AC$4, AD14>=$AD$4), IF(AND(AE14>=$AE$4, AF14>=$AF$4, OR(AG14>=$AG$4, AH14>=$AH$4)), "4", IF(OR(AE14>=$AE$4, AF14>=$AF$4), "3.5", "3")), "2"), "0") -> 3.5 | AO14: =IF(P14>=$P$4, IF(Q14>=$Q$4, IF(R14>=$R$4, IF(S14>=$S$4,4,3), 2), 1), 0) -> 3
A15: 11 | B15: abch23cs@cmrit.ac.in | C15: Abhishek Chataut | D15: =VLOOKUP(B15,USN!$1:$1088,2,FALSE) -> 1CR23CS011 | E15: +977 9766890860 | F15: CSE | H15: 88 | I15: 88 | J15: =IFNA(VLOOKUP(D15,'L3'!$1:$2060,2,False),0) -> 6 | K15: =VLOOKUP(D15,'L4'!$1:$2059,2,FALSE) -> 70 | L15: =VLOOKUP(D15,'A1 RETEST 5 DEC'!$1:$2096,2,FALSE) -> 64 | M15: =VLOOKUP(D15,'A2 RETEST 4 DEC'!$1:$2096,2,FALSE) -> 0 | N15: 18 | P15: =IFNA(VLOOKUP(D15,'S1'!$1:$1325,2,False),0) -> 50 | Q15: =IFNA(vlookup(D15,'S2'!A11:B1213,2,False),0) -> 50 | R15: =ifna(vlookup(D15,'S3'!$1:$1311,2,False),0) -> 0 | T15: 10 | U15: 20 | W15: 32 | AA15: 97.6 | AB15: 84 | AC15: 50 | AD15: 60 | AE15: 15 | AG15: 10 | AK15: =IF(H15>=$H$4, IF(I15>=$I$4, IF(J15>=$J$4, IF(K15>=$K$4, 4, 3), 2), 1), 0) -> 2 | AL15: =IF(L15>=$L$4, IF(M15>=$M$4, IF(N15>=$N$4, IF(O15>=$O$4, 4, 3), 2), 1), 0) -> 1 | AM15: =IF(AND(U15>=$U$4, W15>=$W$4, Y15>=$Y$4, Z15<>"", Z15>=$Z$4), 5, IF(AND(U15>=$U$4, W15>=$W$4, Y15>=$Y$4), 4, IF(AND(U15>=$U$4, W15>=$W$4), 3, IF(AND(T15>=$T$4, U15>=$U$4), 2, 0 ) ) ) ) -> 2 | AN15: =IF(AB15>=$AB$4, IF(OR(AC15>=$AC$4, AD15>=$AD$4), IF(AND(AE15>=$AE$4, AF15>=$AF$4, OR(AG15>=$AG$4, AH15>=$AH$4)), "4", IF(OR(AE15>=$AE$4, AF15>=$AF$4), "3.5", "3")), "2"), "0") -> 3 | AO15: =IF(P15>=$P$4, IF(Q15>=$Q$4, IF(R15>=$R$4, IF(S15>=$S$4,4,3), 2), 1), 0) -> 2
A16: 12 | B16: abhi23cs@cmrit.ac.in | C16: ABHISHEK SOMESHWAR HIREMATH | D16: =VLOOKUP(B16,USN!$1:$1088,2,FALSE) -> 1CR23CS012 | E16: 8217585639 | F16: CSE | H16: 80 | I16: 79 | J16: =IFNA(VLOOKUP(D16,'L3'!$1:$2060,2,False),0) -> 72 | K16: =VLOOKUP(D16,'L4'!$1:$2059,2,FALSE) -> 70 | L16: =VLOOKUP(D16,'A1 RETEST 5 DEC'!$1:$2096,2,FALSE) -> 53 | M16: =VLOOKUP(D16,'A2 RETEST 4 DEC'!$1:$2096,2,FALSE) -> 50 | N16: 50 | P16: =IFNA(VLOOKUP(D16,'S1'!$1:$1325,2,False),0) -> 72 | Q16: =IFNA(vlookup(D16,'S2'!A12:B1214,2,False),0) -> 50 | R16: =ifna(vlookup(D16,'S3'!$1:$1311,2,False),0) -> 74 | T16: 21 | U16: 22 | V16: 80 | W16: 72 | X16: 88 | AA16: 50 | AB16: 82.5 | AC16: 100 | AD16: 81 | AE16: 70 | AG16: 73 | AK16: =IF(H16>=$H$4, IF(I16>=$I$4, IF(J16>=$J$4, IF(K16>=$K$4, 4, 3), 2), 1), 0) -> 4 | AL16: =IF(L16>=$L$4, IF(M16>=$M$4, IF(N16>=$N$4, IF(O16>=$O$4, 4, 3), 2), 1), 0) -> 3 | AM16: =IF(AND(U16>=$U$4, W16>=$W$4, Y16>=$Y$4, Z16<>"", Z16>=$Z$4), 5, IF(AND(U16>=$U$4, W16>=$W$4, Y16>=$Y$4), 4, IF(AND(U16>=$U$4, W16>=$W$4), 3, IF(AND(T16>=$T$4, U16>=$U$4), 2, 0 ) ) ) ) -> 3 | AN16: =IF(AB16>=$AB$4, IF(OR(AC16>=$AC$4, AD16>=$AD$4), IF(AND(AE16>=$AE$4, AF16>=$AF$4, OR(AG16>=$AG$4, AH16>=$AH$4)), "4", IF(OR(AE16>=$AE$4, AF16>=$AF$4), "3.5", "3")), "2"), "0") -> 3.5 | AO16: =IF(P16>=$P$4, IF(Q16>=$Q$4, IF(R16>=$R$4, IF(S16>=$S$4,4,3), 2), 1), 0) -> 3
B17: abro23cs@cmrit.ac.in | C17: ABHISHREYANK ROY R L | D17: =VLOOKUP(B17,USN!$1:$1088,2,FALSE) -> 1CR23CS013 | E17: 9108687358 | F17: CSE | H17: 75 | I17: 74 | J17: =IFNA(VLOOKUP(D17,'L3'!$1:$2060,2,False),0) -> 21 | K17: =VLOOKUP(D17,'L4'!$1:$2059,2,FALSE) -> 6 | L17: =VLOOKUP(D17,'A1 RETEST 5 DEC'!$1:$2096,2,FALSE) -> 33 | M17: =VLOOKUP(D17,'A2 RETEST 4 DEC'!$1:$2096,2,FALSE) -> 0 | N17: 0 | P17: =IFNA(VLOOKUP(D17,'S1'!$1:$1325,2,False),0) -> 0 | Q17: =IFNA(vlookup(D17,'S2'!A13:B1215,2,False),0) -> 0 | R17: =ifna(vlookup(D17,'S3'!$1:$1311,2,False),0) -> 0 | T17: 17 | U17: 18 | AA17: 88 | AB17: 90 | AC17: 0 | AD17: 0 | AE17: 10 | AG17: 0 | AK17: =IF(H17>=$H$4, IF(I17>=$I$4, IF(J17>=$J$4, IF(K17>=$K$4, 4, 3), 2), 1), 0) -> 2 | AL17: =IF(L17>=$L$4, IF(M17>=$M$4, IF(N17>=$N$4, IF(O17>=$O$4, 4, 3), 2), 1), 0) -> 0 | AM17: =IF(AND(U17>=$U$4, W17>=$W$4, Y17>=$Y$4, Z17<>"", Z17>=$Z$4), 5, IF(AND(U17>=$U$4, W17>=$W$4, Y17>=$Y$4), 4, IF(AND(U17>=$U$4, W17>=$W$4), 3, IF(AND(T17>=$T$4, U17>=$U$4), 2, 0 ) ) ) ) -> 2 | AN17: =IF(AB17>=$AB$4, IF(OR(AC17>=$AC$4, AD17>=$AD$4), IF(AND(AE17>=$AE$4, AF17>=$AF$4, OR(AG17>=$AG$4, AH17>=$AH$4)), "4", IF(OR(AE17>=$AE$4, AF17>=$AF$4), "3.5", "3")), "2"), "0") -> 2 | AO17: =IF(P17>=$P$4, IF(Q17>=$Q$4, IF(R17>=$R$4, IF(S17>=$S$4,4,3), 2), 1), 0) -> 0
A18: 13 | B18: abmi23cs@cmrit.ac.in | C18: ABINASH MISHRA | D18: =VLOOKUP(B18,USN!$1:$1088,2,FALSE) -> 1CR23CS014 | E18: 7328048027 | F18: CSE | H18: 86 | I18: 87 | J18: =IFNA(VLOOKUP(D18,'L3'!$1:$2060,2,False),0) -> 75 | K18: =VLOOKUP(D18,'L4'!$1:$2059,2,FALSE) -> 70 | L18: =VLOOKUP(D18,'A1 RETEST 5 DEC'!$1:$2096,2,FALSE) -> 50 | M18: =VLOOKUP(D18,'A2 RETEST 4 DEC'!$1:$2096,2,FALSE) -> 50 | N18: 61 | P18: =IFNA(VLOOKUP(D18,'S1'!$1:$1325,2,False),0) -> 81 | Q18: =IFNA(vlookup(D18,'S2'!A14:B1216,2,False),0) -> 50 | R18: =ifna(vlookup(D18,'S3'!$1:$1311,2,False),0) -> 86 | T18: 13 | U18: 19 | V18: 44 | W18: 40 | X18: 50 | AA18: 100 | AB18: 100 | AC18: 0 | AD18: 60 | AE18: 23 | AG18: 36 | AK18: =IF(H18>=$H$4, IF(I18>=$I$4, IF(J18>=$J$4, IF(K18>=$K$4, 4, 3), 2), 1), 0) -> 4 | AL18: =IF(L18>=$L$4, IF(M18>=$M$4, IF(N18>=$N$4, IF(O18>=$O$4, 4, 3), 2), 1), 0) -> 3 | AM18: =IF(AND(U18>=$U$4, W18>=$W$4, Y18>=$Y$4, Z18<>"", Z18>=$Z$4), 5, IF(AND(U18>=$U$4, W18>=$W$4, Y18>=$Y$4), 4, IF(AND(U18>=$U$4, W18>=$W$4), 3, IF(AND(T18>=$T$4, U18>=$U$4), 2, 0 ) ) ) ) -> 2 | AN18: =IF(AB18>=$AB$4, IF(OR(AC18>=$AC$4, AD18>=$AD$4), IF(AND(AE18>=$AE$4, AF18>=$AF$4, OR(AG18>=$AG$4, AH18>=$AH$4)), "4", IF(OR(AE18>=$AE$4, AF18>=$AF$4), "3.5", "3")), "2"), "0") -> 3 | AO18: =IF(P18>=$P$4, IF(Q18>=$Q$4, IF(R18>=$R$4, IF(S18>=$S$4,4,3), 2), 1), 0) -> 3
A19: 14 | B19: adsy23cs@cmrit.ac.in | C19: ADITHYASY | D19: =VLOOKUP(B19,USN!$1:$1088,2,FALSE) -> 1CR23CS015 | E19: 9008729574 | F19: CSE | H19: 76 | I19: 74 | J19: =IFNA(VLOOKUP(D19,'L3'!$1:$2060,2,False),0) -> 71 | K19: =VLOOKUP(D19,'L4'!$1:$2059,2,FALSE) -> 78 | L19: =VLOOKUP(D19,'A1 RETEST 5 DEC'!$1:$2096,2,FALSE) -> 50 | M19: =VLOOKUP(D19,'A2 RETEST 4 DEC'!$1:$2096,2,FALSE) -> 50 | N19: 54 | P19: =IFNA(VLOOKUP(D19,'S1'!$1:$1325,2,False),0) -> 77 | Q19: =IFNA(vlookup(D19,'S2'!A15:B1217,2,False),0) -> 65 | R19: =ifna(vlookup(D19,'S3'!$1:$1311,2,False),0) -> 91 | T19: 14 | U19: 16 | V19: 68 | W19: 56 | X19: 82 | AA19: 78 | AB19: 95 | AC19: 98 | AD19: 100 | AE19: 81 | AG19: 78 | AK19: =IF(H19>=$H$4, IF(I19>=$I$4, IF(J19>=$J$4, IF(K19>=$K$4, 4, 3), 2), 1), 0) -> 4 | AL19: =IF(L19>=$L$4, IF(M19>=$M$4, IF(N19>=$N$4, IF(O19>=$O$4, 4, 3), 2), 1), 0) -> 3 | AM19: =IF(AND(U19>=$U$4, W19>=$W$4, Y19>=$Y$4, Z19<>"", Z19>=$Z$4), 5, IF(AND(U19>=$U$4, W19>=$W$4, Y19>=$Y$4), 4, IF(AND(U19>=$U$4, W19>=$W$4), 3, IF(AND(T19>=$T$4, U19>=$U$4), 2, 0 ) ) ) ) -> 3 | AN19: =IF(AB19>=$AB$4, IF(OR(AC19>=$AC$4, AD19>=$AD$4), IF(AND(AE19>=$AE$4, AF19>=$AF$4, OR(AG19>=$AG$4, AH19>=$AH$4)), "4", IF(OR(AE19>=$AE$4, AF19>=$AF$4), "3.5", "3")), "2"), "0") -> 3.5 | AO19: =IF(P19>=$P$4, IF(Q19>=$Q$4, IF(R19>=$R$4, IF(S19>=$S$4,4,3), 2), 1), 0) -> 3
A20: 15 | B20: adbh23cs@cmrit.ac.in | C20: Aditya Bhusal | D20: =VLOOKUP(B20,USN!$1:$1088,2,FALSE) -> 1CR23CS016 | E20: =+9779765503446 -> 9779765503446 | F20: CSE | H20: 79 | I20: 72 | J20: =IFNA(VLOOKUP(D20,'L3'!$1:$2060,2,False),0) -> 33 | K20: =VLOOKUP(D20,'L4'!$1:$2059,2,FALSE) -> 6 | L20: =VLOOKUP(D20,'A1 RETEST 5 DEC'!$1:$2096,2,FALSE) -> 11 | M20: =VLOOKUP(D20,'A2 RETEST 4 DEC'!$1:$2096,2,FALSE) -> 7 | N20: 0 | P20: =IFNA(VLOOKUP(D20,'S1'!$1:$1325,2,False),0) -> 0 | Q20: =IFNA(vlookup(D20,'S2'!A16:B1218,2,False),0) -> 0 | R20: =ifna(vlookup(D20,'S3'!$1:$1311,2,False),0) -> 0 | T20: 11 | U20: Ab | V20: 76 | AA20: 0 | AB20: 38 | AC20: 0 | AD20: 0 | AE20: 10 | AG20: 10 | AK20: =IF(H20>=$H$4, IF(I20>=$I$4, IF(J20>=$J$4, IF(K20>=$K$4, 4, 3), 2), 1), 0) -> 2 | AL20: =IF(L20>=$L$4, IF(M20>=$M$4, IF(N20>=$N$4, IF(O20>=$O$4, 4, 3), 2), 1), 0) -> 0 | AM20: =IF(AND(U20>=$U$4, W20>=$W$4, Y20>=$Y$4, Z20<>"", Z20>=$Z$4), 5, IF(AND(U20>=$U$4, W20>=$W$4, Y20>=$Y$4), 4, IF(AND(U20>=$U$4, W20>=$W$4), 3, IF(AND(T20>=$T$4, U20>=$U$4), 2, 0 ) ) ) ) -> 2 | AN20: =IF(AB20>=$AB$4, IF(OR(AC20>=$AC$4, AD20>=$AD$4), IF(AND(AE20>=$AE$4, AF20>=$AF$4, OR(AG20>=$AG$4, AH20>=$AH$4)), "4", IF(OR(AE20>=$AE$4, AF20>=$AF$4), "3.5", "3")), "2"), "0") -> 0 | AO20: =IF(P20>=$P$4, IF(Q20>=$Q$4, IF(R20>=$R$4, IF(S20>=$S$4,4,3), 2), 1), 0) -> 0
A21: 16 | B21: adpr23cs@cmrit.ac.in | C21: Aditya Prakash | D21: =VLOOKUP(B21,USN!$1:$1088,2,FALSE) -> 1CR23CS017 | E21: 8969143681 | F21: CSE | H21: 79 | I21: 83 | J21: =IFNA(VLOOKUP(D21,'L3'!$1:$2060,2,False),0) -> 70 | K21: =VLOOKUP(D21,'L4'!$1:$2059,2,FALSE) -> 70 | L21: =VLOOKUP(D21,'A1 RETEST 5 DEC'!$1:$2096,2,FALSE) -> 72 | M21: =VLOOKUP(D21,'A2 RETEST 4 DEC'!$1:$2096,2,FALSE) -> 4 | N21: 52 | P21: =IFNA(VLOOKUP(D21,'S1'!$1:$1325,2,False),0) -> 0 | Q21: =IFNA(vlookup(D21,'S2'!A17:B1219,2,False),0) -> 63 | R21: =ifna(vlookup(D21,'S3'!$1:$1311,2,False),0) -> 80 | T21: 10 | U21: 22 | V21: 84 | W21: 32 | X21: 78 | AA21: 74 | AB21: 100 | AC21: 75 | AD21: 75 | AE21: 72 | AG21: 40 | AK21: =IF(H21>=$H$4, IF(I21>=$I$4, IF(J21>=$J$4, IF(K21>=$K$4, 4, 3), 2), 1), 0) -> 4 | AL21: =IF(L21>=$L$4, IF(M21>=$M$4, IF(N21>=$N$4, IF(O21>=$O$4, 4, 3), 2), 1), 0) -> 1 | AM21: =IF(AND(U21>=$U$4, W21>=$W$4, Y21>=$Y$4, Z21<>"", Z21>=$Z$4), 5, IF(AND(U21>=$U$4, W21>=$W$4, Y21>=$Y$4), 4, IF(AND(U21>=$U$4, W21>=$W$4), 3, IF(AND(T21>=$T$4, U21>=$U$4), 2, 0 ) ) ) ) -> 2 | AN21: =IF(AB21>=$AB$4, IF(OR(AC21>=$AC$4, AD21>=$AD$4), IF(AND(AE21>=$AE$4, AF21>=$AF$4, OR(AG21>=$AG$4, AH21>=$AH$4)), "4", IF(OR(AE21>=$AE$4, AF21>=$AF$4), "3.5", "3")), "2"), "0") -> 3.5 | AO21: =IF(P21>=$P$4, IF(Q21>=$Q$4, IF(R21>=$R$4, IF(S21>=$S$4,4,3), 2), 1), 0) -> 0
A22: 17 | B22: adha23cs@cmrit.ac.in | C22: Advait Harish | D22: =VLOOKUP(B22,USN!$1:$1088,2,FALSE) -> 1CR23CS018 | E22: 9686313405 | F22: CSE | H22: 89 | I22: 89 | J22: =IFNA(VLOOKUP(D22,'L3'!$1:$2060,2,False),0) -> 88 | K22: =VLOOKUP(D22,'L4'!$1:$2059,2,FALSE) -> 72 | L22: =VLOOKUP(D22,'A1 RETEST 5 DEC'!$1:$2096,2,FALSE) -> 72 | M22: =VLOOKUP(D22,'A2 RETEST 4 DEC'!$1:$2096,2,FALSE) -> 50 | N22: 50 | P22: =IFNA(VLOOKUP(D22,'S1'!$1:$1325,2,False),0) -> 78 | Q22: =IFNA(vlookup(D22,'S2'!A18:B1220,2,False),0) -> 73 | R22: =ifna(vlookup(D22,'S3'!$1:$1311,2,False),0) -> 84 | T22: 14 | U22: 18 | V22: 75 | W22: 56 | X22: 86 | AA22: 99 | AB22: 100 | AC22: 98.5 | AD22: 74 | AE22: 87 | AG22: 73 | AK22: =IF(H22>=$H$4, IF(I22>=$I$4, IF(J22>=$J$4, IF(K22>=$K$4, 4, 3), 2), 1), 0) -> 4 | AL22: =IF(L22>=$L$4, IF(M22>=$M$4, IF(N22>=$N$4, IF(O22>=$O$4, 4, 3), 2), 1), 0) -> 3 | AM22: =IF(AND(U22>=$U$4, W22>=$W$4, Y22>=$Y$4, Z22<>"", Z22>=$Z$4), 5, IF(AND(U22>=$U$4, W22>=$W$4, Y22>=$Y$4), 4, IF(AND(U22>=$U$4, W22>=$W$4), 3, IF(AND(T22>=$T$4, U22>=$U$4), 2, 0 ) ) ) ) -> 3 | AN22: =IF(AB22>=$AB$4, IF(OR(AC22>=$AC$4, AD22>=$AD$4), IF(AND(AE22>=$AE$4, AF22>=$AF$4, OR(AG22>=$AG$4, AH22>=$AH$4)), "4", IF(OR(AE22>=$AE$4, AF22>=$AF$4), "3.5", "3")), "2"), "0") -> 3.5 | AO22: =IF(P22>=$P$4, IF(Q22>=$Q$4, IF(R22>=$R$4, IF(S22>=$S$4,4,3), 2), 1), 0) -> 3
A23: 18 | B23: adsa23cs@cmrit.ac.in | C23: ADVAIT SACHIN KESKAR | D23: =VLOOKUP(B23,USN!$1:$1088,2,FALSE) -> 1CR23CS019 | E23: 8792477272 | F23: CSE | H23: 89 | I23: 78 | J23: =IFNA(VLOOKUP(D23,'L3'!$1:$2060,2,False),0) -> 60 | K23: =VLOOKUP(D23,'L4'!$1:$2059,2,FALSE) -> 37 | L23: =VLOOKUP(D23,'A1 RETEST 5 DEC'!$1:$2096,2,FALSE) -> 33 | M23: =VLOOKUP(D23,'A2 RETEST 4 DEC'!$1:$2096,2,FALSE) -> 0 | N23: 6 | P23: =IFNA(VLOOKUP(D23,'S1'!$1:$1325,2,False),0) -> 0 | Q23: =IFNA(vlookup(D23,'S2'!A19:B1221,2,False),0) -> 0 | R23: =ifna(vlookup(D23,'S3'!$1:$1311,2,False),0) -> 0 | T23: 14 | U23: 15 | V23: 32 | W23: 44 | AA23: 54 | AB23: 35 | AC23: 0 | AD23: 0 | AE23: 10 | AG23: 0 | AK23: =IF(H23>=$H$4, IF(I23>=$I$4, IF(J23>=$J$4, IF(K23>=$K$4, 4, 3), 2), 1), 0) -> 2 | AL23: =IF(L23>=$L$4, IF(M23>=$M$4, IF(N23>=$N$4, IF(O23>=$O$4, 4, 3), 2), 1), 0) -> 0 | AM23: =IF(AND(U23>=$U$4, W23>=$W$4, Y23>=$Y$4, Z23<>"", Z23>=$Z$4), 5, IF(AND(U23>=$U$4, W23>=$W$4, Y23>=$Y$4), 4, IF(AND(U23>=$U$4, W23>=$W$4), 3, IF(AND(T23>=$T$4, U23>=$U$4), 2, 0 ) ) ) ) -> 2 | AN23: =IF(AB23>=$AB$4, IF(OR(AC23>=$AC$4, AD23>=$AD$4), IF(AND(AE23>=$AE$4, AF23>=$AF$4, OR(AG23>=$AG$4, AH23>=$AH$4)), "4", IF(OR(AE23>=$AE$4, AF23>=$AF$4), "3.5", "3")), "2"), "0") -> 0 | AO23: =IF(P23>=$P$4, IF(Q23>=$Q$4, IF(R23>=$R$4, IF(S23>=$S$4,4,3), 2), 1), 0) -> 0
A24: 19 | B24: aish23cs@cmrit.ac.in | C24: AISHWARYA SHARABANNAGOUDA MALIPATIL | D24: =VLOOKUP(B24,USN!$1:$1088,2,FALSE) -> 1CR23CS020 | E24: 9019105930 | F24: CSE | H24: 71 | I24: 74 | J24: =IFNA(VLOOKUP(D24,'L3'!$1:$2060,2,False),0) -> 70 | K24: =VLOOKUP(D24,'L4'!$1:$2059,2,FALSE) -> 70 | L24: =VLOOKUP(D24,'A1 RETEST 5 DEC'!$1:$2096,2,FALSE) -> 50 | M24: =VLOOKUP(D24,'A2 RETEST 4 DEC'!$1:$2096,2,FALSE) -> 13 | N24: 50 | P24: =IFNA(VLOOKUP(D24,'S1'!$1:$1325,2,False),0) -> 87 | Q24: =IFNA(vlookup(D24,'S2'!A20:B1222,2,False),0) -> 66 | R24: =ifna(vlookup(D24,'S3'!$1:$1311,2,False),0) -> 83 | T24: 12 | U24: 17 | V24: 85 | W24: 40 | X24: 86 | AA24: 100 | AB24: 97.5 | AC24: 62.5 | AD24: 100 | AE24: 25 | AG24: 71 | AK24: =IF(H24>=$H$4, IF(I24>=$I$4, IF(J24>=$J$4, IF(K24>=$K$4, 4, 3), 2), 1), 0) -> 4 | AL24: =IF(L24>=$L$4, IF(M24>=$M$4, IF(N24>=$N$4, IF(O24>=$O$4, 4, 3), 2), 1), 0) -> 1 | AM24: =IF(AND(U24>=$U$4, W24>=$W$4, Y24>=$Y$4, Z24<>"", Z24>=$Z$4), 5, IF(AND(U24>=$U$4, W24>=$W$4, Y24>=$Y$4), 4, IF(AND(U24>=$U$4, W24>=$W$4), 3, IF(AND(T24>=$T$4, U24>=$U$4), 2, 0 ) ) ) ) -> 2 | AN24: =IF(AB24>=$AB$4, IF(OR(AC24>=$AC$4, AD24>=$AD$4), IF(AND(AE24>=$AE$4, AF24>=$AF$4, OR(AG24>=$AG$4, AH24>=$AH$4)), "4", IF(OR(AE24>=$AE$4, AF24>=$AF$4), "3.5", "3")), "2"), "0") -> 3 | AO24: =IF(P24>=$P$4, IF(Q24>=$Q$4, IF(R24>=$R$4, IF(S24>=$S$4,4,3), 2), 1), 0) -> 3
A25: 20 | B25: aiai23cs@cmrit.ac.in | C25: Aishwarya sujan | D25: =VLOOKUP(B25,USN!$1:$1088,2,FALSE) -> 1CR23CS021 | E25: 8296162379 | F25: CSE | H25: 88 | I25: 90 | J25: =IFNA(VLOOKUP(D25,'L3'!$1:$2060,2,False),0) -> 92 | K25: =VLOOKUP(D25,'L4'!$1:$2059,2,FALSE) -> 77 | L25: =VLOOKUP(D25,'A1 RETEST 5 DEC'!$1:$2096,2,FALSE) -> 50 | M25: =VLOOKUP(D25,'A2 RETEST 4 DEC'!$1:$2096,2,FALSE) -> 28 | N25: 50 | P25: =IFNA(VLOOKUP(D25,'S1'!$1:$1325,2,False),0) -> 77 | Q25: =IFNA(vlookup(D25,'S2'!A21:B1223,2,False),0) -> 73 | R25: =ifna(vlookup(D25,'S3'!$1:$1311,2,False),0) -> 93 | T25: 10 | U25: 20 | V25: 80 | W25: 56 | X25: 88 | AA25: 94 | AB25: 100 | AC25: 63.5 | AD25: 68 | AE25: 77 | AG25: 63 | AK25: =IF(H25>=$H$4, IF(I25>=$I$4, IF(J25>=$J$4, IF(K25>=$K$4, 4, 3), 2), 1), 0) -> 4 | AL25: =IF(L25>=$L$4, IF(M25>=$M$4, IF(N25>=$N$4, IF(O25>=$O$4, 4, 3), 2), 1), 0) -> 1 | AM25: =IF(AND(U25>=$U$4, W25>=$W$4, Y25>=$Y$4, Z25<>"", Z25>=$Z$4), 5, IF(AND(U25>=$U$4, W25>=$W$4, Y25>=$Y$4), 4, IF(AND(U25>=$U$4, W25>=$W$4), 3, IF(AND(T25>=$T$4, U25>=$U$4), 2, 0 ) ) ) ) -> 3 | AN25: =IF(AB25>=$AB$4, IF(OR(AC25>=$AC$4, AD25>=$AD$4), IF(AND(AE25>=$AE$4, AF25>=$AF$4, OR(AG25>=$AG$4, AH25>=$AH$4)), "4", IF(OR(AE25>=$AE$4, AF25>=$AF$4), "3.5", "3")), "2"), "0") -> 3.5 | AO25: =IF(P25>=$P$4, IF(Q25>=$Q$4, IF(R25>=$R$4, IF(S25>=$S$4,4,3), 2), 1), 0) -> 3
A26: 21 | B26: aj23cs@cmrit.ac.in | C26: Ajay | D26: =VLOOKUP(B26,USN!$1:$1088,2,FALSE) -> 1CR23CS022 | E26: 8830894731 | F26: CSE | H26: 73 | I26: 75 | J26: =IFNA(VLOOKUP(D26,'L3'!$1:$2060,2,False),0) -> 61 | K26: =VLOOKUP(D26,'L4'!$1:$2059,2,FALSE) -> 70 | L26: =VLOOKUP(D26,'A1 RETEST 5 DEC'!$1:$2096,2,FALSE) -> 58 | M26: =VLOOKUP(D26,'A2 RETEST 4 DEC'!$1:$2096,2,FALSE) -> 25 | N26: 13 | P26: =IFNA(VLOOKUP(D26,'S1'!$1:$1325,2,False),0) -> 50 | Q26: =IFNA(vlookup(D26,'S2'!A22:B1224,2,False),0) -> 0 | R26: =ifna(vlookup(D26,'S3'!$1:$1311,2,False),0) -> 50 | T26: 20 | U26: 17 | V26: 68 | W26: 40 | X26: 88 | AA26: 42 | AB26: 55 | AC26: 12.5 | AD26: 70 | AE26: 24 | AG26: 5 | AK26: =IF(H26>=$H$4, IF(I26>=$I$4, IF(J26>=$J$4, IF(K26>=$K$4, 4, 3), 2), 1), 0) -> 2 | AL26: =IF(L26>=$L$4, IF(M26>=$M$4, IF(N26>=$N$4, IF(O26>=$O$4, 4, 3), 2), 1), 0) -> 1 | AM26: =IF(AND(U26>=$U$4, W26>=$W$4, Y26>=$Y$4, Z26<>"", Z26>=$Z$4), 5, IF(AND(U26>=$U$4, W26>=$W$4, Y26>=$Y$4), 4, IF(AND(U26>=$U$4, W26>=$W$4), 3, IF(AND(T26>=$T$4, U26>=$U$4), 2, 0 ) ) ) ) -> 2 | AN26: =IF(AB26>=$AB$4, IF(OR(AC26>=$AC$4, AD26>=$AD$4), IF(AND(AE26>=$AE$4, AF26>=$AF$4, OR(AG26>=$AG$4, AH26>=$AH$4)), "4", IF(OR(AE26>=$AE$4, AF26>=$AF$4), "3.5", "3")), "2"), "0") -> 3 | AO26: =IF(P26>=$P$4, IF(Q26>=$Q$4, IF(R26>=$R$4, IF(S26>=$S$4,4,3), 2), 1), 0) -> 1
A27: 22 | B27: ajk23cs@cmrit.ac.in | C27: AJEYA KUMARA K | D27: =VLOOKUP(B27,USN!$1:$1088,2,FALSE) -> 1CR23CS023 | E27: 9019841504 | F27: CSE | H27: 74 | I27: 76 | J27: =IFNA(VLOOKUP(D27,'L3'!$1:$2060,2,False),0) -> 70 | K27: =VLOOKUP(D27,'L4'!$1:$2059,2,FALSE) -> 75 | L27: =VLOOKUP(D27,'A1 RETEST 5 DEC'!$1:$2096,2,FALSE) -> 53 | M27: =VLOOKUP(D27,'A2 RETEST 4 DEC'!$1:$2096,2,FALSE) -> 50 | N27: 52 | P27: =IFNA(VLOOKUP(D27,'S1'!$1:$1325,2,False),0) -> 75 | Q27: =IFNA(vlookup(D27,'S2'!A23:B1225,2,False),0) -> 62 | R27: =ifna(vlookup(D27,'S3'!$1:$1311,2,False),0) -> 80 | T27: 20 | U27: 18 | V27: 64 | W27: 64 | X27: 86 | AA27: 100 | AB27: 60 | AC27: 100 | AD27: 88 | AE27: 80 | AG27: 76 | AK27: =IF(H27>=$H$4, IF(I27>=$I$4, IF(J27>=$J$4, IF(K27>=$K$4, 4, 3), 2), 1), 0) -> 4 | AL27: =IF(L27>=$L$4, IF(M27>=$M$4, IF(N27>=$N$4, IF(O27>=$O$4, 4, 3), 2), 1), 0) -> 3 | AM27: =IF(AND(U27>=$U$4, W27>=$W$4, Y27>=$Y$4, Z27<>"", Z27>=$Z$4), 5, IF(AND(U27>=$U$4, W27>=$W$4, Y27>=$Y$4), 4, IF(AND(U27>=$U$4, W27>=$W$4), 3, IF(AND(T27>=$T$4, U27>=$U$4), 2, 0 ) ) ) ) -> 3 | AN27: =IF(AB27>=$AB$4, IF(OR(AC27>=$AC$4, AD27>=$AD$4), IF(AND(AE27>=$AE$4, AF27>=$AF$4, OR(AG27>=$AG$4, AH27>=$AH$4)), "4", IF(OR(AE27>=$AE$4, AF27>=$AF$4), "3.5", "3")), "2"), "0") -> 3.5 | AO27: =IF(P27>=$P$4, IF(Q27>=$Q$4, IF(R27>=$R$4, IF(S27>=$S$4,4,3), 2), 1), 0) -> 3
A28: 23 | B28: akbv23cs@cmrit.ac.in | C28: AKASH B V | D28: =VLOOKUP(B28,USN!$1:$1088,2,FALSE) -> 1CR23CS024 | E28: 7022615568 | F28: CSE | H28: 77 | I28: 82 | J28: =IFNA(VLOOKUP(D28,'L3'!$1:$2060,2,False),0) -> 70 | K28: =VLOOKUP(D28,'L4'!$1:$2059,2,FALSE) -> 75 | L28: =VLOOKUP(D28,'A1 RETEST 5 DEC'!$1:$2096,2,FALSE) -> 59 | M28: =VLOOKUP(D28,'A2 RETEST 4 DEC'!$1:$2096,2,FALSE) -> 25 | N28: 0 | P28: =IFNA(VLOOKUP(D28,'S1'!$1:$1325,2,False),0) -> 77 | Q28: =IFNA(vlookup(D28,'S2'!A24:B1226,2,False),0) -> 62 | R28: =ifna(vlookup(D28,'S3'!$1:$1311,2,False),0) -> 0 | T28: 12 | U28: 17 | V28: 68 | W28: 48 | AA28: 98 | AB28: 100 | AC28: 60 | AD28: 62 | AE28: 10 | AG28: 5 | AK28: =IF(H28>=$H$4, IF(I28>=$I$4, IF(J28>=$J$4, IF(K28>=$K$4, 4, 3), 2), 1), 0) -> 4 | AL28: =IF(L28>=$L$4, IF(M28>=$M$4, IF(N28>=$N$4, IF(O28>=$O$4, 4, 3), 2), 1), 0) -> 1 | AM28: =IF(AND(U28>=$U$4, W28>=$W$4, Y28>=$Y$4, Z28<>"", Z28>=$Z$4), 5, IF(AND(U28>=$U$4, W28>=$W$4, Y28>=$Y$4), 4, IF(AND(U28>=$U$4, W28>=$W$4), 3, IF(AND(T28>=$T$4, U28>=$U$4), 2, 0 ) ) ) ) -> 2 | AN28: =IF(AB28>=$AB$4, IF(OR(AC28>=$AC$4, AD28>=$AD$4), IF(AND(AE28>=$AE$4, AF28>=$AF$4, OR(AG28>=$AG$4, AH28>=$AH$4)), "4", IF(OR(AE28>=$AE$4, AF28>=$AF$4), "3.5", "3")), "2"), "0") -> 3 | AO28: =IF(P28>=$P$4, IF(Q28>=$Q$4, IF(R28>=$R$4, IF(S28>=$S$4,4,3), 2), 1), 0) -> 2
A29: 24 | B29: akj23cs@cmrit.ac.in | C29: AKASH J | D29: =VLOOKUP(B29,USN!$1:$1088,2,FALSE) -> 1CR23CS025 | E29: 7349119348 | F29: CSE | H29: 71 | I29: 69 | J29: =IFNA(VLOOKUP(D29,'L3'!$1:$2060,2,False),0) -> 45 | K29: =VLOOKUP(D29,'L4'!$1:$2059,2,FALSE) -> 24 | L29: =VLOOKUP(D29,'A1 RETEST 5 DEC'!$1:$2096,2,FALSE) -> 34 | M29: =VLOOKUP(D29,'A2 RETEST 4 DEC'!$1:$2096,2,FALSE) -> 15 | N29: 0 | P29: =IFNA(VLOOKUP(D29,'S1'!$1:$1325,2,False),0) -> 0 | Q29: =IFNA(vlookup(D29,'S2'!A25:B1227,2,False),0) -> 0 | R29: =ifna(vlookup(D29,'S3'!$1:$1311,2,False),0) -> 0 | T29: 18 | U29: 20 | V29: 76 | W29: 28 | X29: 82 | AA29: 20 | AB29: 78.75 | AC29: 0 | AD29: 76 | AE29: 10 | AG29: 0 | AK29: =IF(H29>=$H$4, IF(I29>=$I$4, IF(J29>=$J$4, IF(K29>=$K$4, 4, 3), 2), 1), 0) -> 2 | AL29: =IF(L29>=$L$4, IF(M29>=$M$4, IF(N29>=$N$4, IF(O29>=$O$4, 4, 3), 2), 1), 0) -> 0 | AM29: =IF(AND(U29>=$U$4, W29>=$W$4, Y29>=$Y$4, Z29<>"", Z29>=$Z$4), 5, IF(AND(U29>=$U$4, W29>=$W$4, Y29>=$Y$4), 4, IF(AND(U29>=$U$4, W29>=$W$4), 3, IF(AND(T29>=$T$4, U29>=$U$4), 2, 0 ) ) ) ) -> 2 | AN29: =IF(AB29>=$AB$4, IF(OR(AC29>=$AC$4, AD29>=$AD$4), IF(AND(AE29>=$AE$4, AF29>=$AF$4, OR(AG29>=$AG$4, AH29>=$AH$4)), "4", IF(OR(AE29>=$AE$4, AF29>=$AF$4), "3.5", "3")), "2"), "0") -> 3 | AO29: =IF(P29>=$P$4, IF(Q29>=$Q$4, IF(R29>=$R$4, IF(S29>=$S$4,4,3), 2), 1), 0) -> 0
A30: 25 | B30: ak23cs@cmrit.ac.in | C30: Akshaya | D30: =VLOOKUP(B30,USN!$1:$1088,2,FALSE) -> 1CR23CS026 | E30: 9916845777 | F30: CSE | H30: 83 | I30: 89 | J30: =IFNA(VLOOKUP(D30,'L3'!$1:$2060,2,False),0) -> 70 | K30: =VLOOKUP(D30,'L4'!$1:$2059,2,FALSE) -> 73 | L30: =VLOOKUP(D30,'A1 RETEST 5 DEC'!$1:$2096,2,FALSE) -> 50 | M30: =VLOOKUP(D30,'A2 RETEST 4 DEC'!$1:$2096,2,FALSE) -> 50 | N30: 50 | P30: =IFNA(VLOOKUP(D30,'S1'!$1:$1325,2,False),0) -> 78 | Q30: =IFNA(vlookup(D30,'S2'!A26:B1228,2,False),0) -> 66 | R30: =ifna(vlookup(D30,'S3'!$1:$1311,2,False),0) -> 89 | T30: 18 | U30: 22 | V30: 72 | W30: 40 | X30: 82 | AA30: 100 | AB30: 100 | AC30: 80 | AD30: 100 | AE30: 76 | AG30: 78 | AK30: =IF(H30>=$H$4, IF(I30>=$I$4, IF(J30>=$J$4, IF(K30>=$K$4, 4, 3), 2), 1), 0) -> 4 | AL30: =IF(L30>=$L$4, IF(M30>=$M$4, IF(N30>=$N$4, IF(O30>=$O$4, 4, 3), 2), 1), 0) -> 3 | AM30: =IF(AND(U30>=$U$4, W30>=$W$4, Y30>=$Y$4, Z30<>"", Z30>=$Z$4), 5, IF(AND(U30>=$U$4, W30>=$W$4, Y30>=$Y$4), 4, IF(AND(U30>=$U$4, W30>=$W$4), 3, IF(AND(T30>=$T$4, U30>=$U$4), 2, 0 ) ) ) ) -> 2 | AN30: =IF(AB30>=$AB$4, IF(OR(AC30>=$AC$4, AD30>=$AD$4), IF(AND(AE30>=$AE$4, AF30>=$AF$4, OR(AG30>=$AG$4, AH30>=$AH$4)), "4", IF(OR(AE30>=$AE$4, AF30>=$AF$4), "3.5", "3")), "2"), "0") -> 3.5 | AO30: =IF(P30>=$P$4, IF(Q30>=$Q$4, IF(R30>=$R$4, IF(S30>=$S$4,4,3), 2), 1), 0) -> 3
A31: 26 | B31: akri23cs@cmrit.ac.in | C31: AKUMALLA RITHEESHA | D31: =VLOOKUP(B31,USN!$1:$1088,2,FALSE) -> 1CR23CS027 | E31: 8885303717 | F31: CSE | H31: 87 | I31: 89 | J31: =IFNA(VLOOKUP(D31,'L3'!$1:$2060,2,False),0) -> 79 | K31: =VLOOKUP(D31,'L4'!$1:$2059,2,FALSE) -> 70 | L31: =VLOOKUP(D31,'A1 RETEST 5 DEC'!$1:$2096,2,FALSE) -> 78 | M31: =VLOOKUP(D31,'A2 RETEST 4 DEC'!$1:$2096,2,FALSE) -> 50 | N31: 50 | P31: =IFNA(VLOOKUP(D31,'S1'!$1:$1325,2,False),0) -> 83 | Q31: =IFNA(vlookup(D31,'S2'!A27:B1229,2,False),0) -> 65 | R31: =ifna(vlookup(D31,'S3'!$1:$1311,2,False),0) -> 92 | T31: 11 | U31: 22 | V31: 72 | W31: 28 | X31: 92 | AA31: 50 | AB31: 77.5 | AC31: 60 | AD31: 75 | AE31: 33 | AG31: 46 | AK31: =IF(H31>=$H$4, IF(I31>=$I$4, IF(J31>=$J$4, IF(K31>=$K$4, 4, 3), 2), 1), 0) -> 4 | AL31: =IF(L31>=$L$4, IF(M31>=$M$4, IF(N31>=$N$4, IF(O31>=$O$4, 4, 3), 2), 1), 0) -> 3 | AM31: =IF(AND(U31>=$U$4, W31>=$W$4, Y31>=$Y$4, Z31<>"", Z31>=$Z$4), 5, IF(AND(U31>=$U$4, W31>=$W$4, Y31>=$Y$4), 4, IF(AND(U31>=$U$4, W31>=$W$4), 3, IF(AND(T31>=$T$4, U31>=$U$4), 2, 0 ) ) ) ) -> 2 | AN31: =IF(AB31>=$AB$4, IF(OR(AC31>=$AC$4, AD31>=$AD$4), IF(AND(AE31>=$AE$4, AF31>=$AF$4, OR(AG31>=$AG$4, AH31>=$AH$4)), "4", IF(OR(AE31>=$AE$4, AF31>=$AF$4), "3.5", "3")), "2"), "0") -> 3 | AO31: =IF(P31>=$P$4, IF(Q31>=$Q$4, IF(R31>=$R$4, IF(S31>=$S$4,4,3), 2), 1), 0) -> 3
A32: 27 | B32: alja23cs@cmrit.ac.in | C32: ALLAMPRABHU S JANGAMASHETTI | D32: =VLOOKUP(B32,USN!$1:$1088,2,FALSE) -> 1CR23CS028 | E32: 9620590906 | F32: CSE | H32: 75 | I32: 80 | J32: =IFNA(VLOOKUP(D32,'L3'!$1:$2060,2,False),0) -> 48 | K32: =VLOOKUP(D32,'L4'!$1:$2059,2,FALSE) -> 70 | L32: =VLOOKUP(D32,'A1 RETEST 5 DEC'!$1:$2096,2,FALSE) -> 50 | M32: =VLOOKUP(D32,'A2 RETEST 4 DEC'!$1:$2096,2,FALSE) -> 50 | N32: 0 | P32: =IFNA(VLOOKUP(D32,'S1'!$1:$1325,2,False),0) -> 50 | Q32: =IFNA(vlookup(D32,'S2'!A28:B1230,2,False),0) -> 0 | R32: =ifna(vlookup(D32,'S3'!$1:$1311,2,False),0) -> 0 | T32: 18 | U32: 19 | W32: 24 | X32: 80 | AA32: 30 | AB32: 17.5 | AC32: 80 | AD32: 100 | AE32: 14 | AG32: 0 | AK32: =IF(H32>=$H$4, IF(I32>=$I$4, IF(J32>=$J$4, IF(K32>=$K$4, 4, 3), 2), 1), 0) -> 2 | AL32: =IF(L32>=$L$4, IF(M32>=$M$4, IF(N32>=$N$4, IF(O32>=$O$4, 4, 3), 2), 1), 0) -> 2 | AM32: =IF(AND(U32>=$U$4, W32>=$W$4, Y32>=$Y$4, Z32<>"", Z32>=$Z$4), 5, IF(AND(U32>=$U$4, W32>=$W$4, Y32>=$Y$4), 4, IF(AND(U32>=$U$4, W32>=$W$4), 3, IF(AND(T32>=$T$4, U32>=$U$4), 2, 0 ) ) ) ) -> 2 | AN32: =IF(AB32>=$AB$4, IF(OR(AC32>=$AC$4, AD32>=$AD$4), IF(AND(AE32>=$AE$4, AF32>=$AF$4, OR(AG32>=$AG$4, AH32>=$AH$4)), "4", IF(OR(AE32>=$AE$4, AF32>=$AF$4), "3.5", "3")), "2"), "0") -> 0 | AO32: =IF(P32>=$P$4, IF(Q32>=$Q$4, IF(R32>=$R$4, IF(S32>=$S$4,4,3), 2), 1), 0) -> 1
A33: 28 | B33: amku23cs@cmrit.ac.in | C33: Aman kumar pathak | D33: =VLOOKUP(B33,USN!$1:$1088,2,FALSE) -> 1CR23CS029 | E33: NA | F33: CSE | H33: 72 | I33: 70 | J33: =IFNA(VLOOKUP(D33,'L3'!$1:$2060,2,False),0) -> 31 | K33: =VLOOKUP(D33,'L4'!$1:$2059,2,FALSE) -> 70 | L33: =VLOOKUP(D33,'A1 RETEST 5 DEC'!$1:$2096,2,FALSE) -> 53 | M33: =VLOOKUP(D33,'A2 RETEST 4 DEC'!$1:$2096,2,FALSE) -> 15 | N33: 9 | P33: =IFNA(VLOOKUP(D33,'S1'!$1:$1325,2,False),0) -> 0 | Q33: =IFNA(vlookup(D33,'S2'!A29:B1231,2,False),0) -> 0 | R33: =ifna(vlookup(D33,'S3'!$1:$1311,2,False),0) -> 0 | T33: 19 | U33: 17 | W33: 20 | X33: 90 | AA33: 28 | AB33: 85 | AC33: 0 | AD33: 26 | AE33: 10 | AG33: 18 | AK33: =IF(H33>=$H$4, IF(I33>=$I$4, IF(J33>=$J$4, IF(K33>=$K$4, 4, 3), 2), 1), 0) -> 2 | AL33: =IF(L33>=$L$4, IF(M33>=$M$4, IF(N33>=$N$4, IF(O33>=$O$4, 4, 3), 2), 1), 0) -> 1 | AM33: =IF(AND(U33>=$U$4, W33>=$W$4, Y33>=$Y$4, Z33<>"", Z33>=$Z$4), 5, IF(AND(U33>=$U$4, W33>=$W$4, Y33>=$Y$4), 4, IF(AND(U33>=$U$4, W33>=$W$4), 3, IF(AND(T33>=$T$4, U33>=$U$4), 2, 0 ) ) ) ) -> 2 | AN33: =IF(AB33>=$AB$4, IF(OR(AC33>=$AC$4, AD33>=$AD$4), IF(AND(AE33>=$AE$4, AF33>=$AF$4, OR(AG33>=$AG$4, AH33>=$AH$4)), "4", IF(OR(AE33>=$AE$4, AF33>=$AF$4), "3.5", "3")), "2"), "0") -> 2 | AO33: =IF(P33>=$P$4, IF(Q33>=$Q$4, IF(R33>=$R$4, IF(S33>=$S$4,4,3), 2), 1), 0) -> 0
A34: 29 | B34: anki23cs@cmrit.ac.in | C34: ANAND KISHOR | D34: =VLOOKUP(B34,USN!$1:$1088,2,FALSE) -> 1CR23CS030 | E34: 9546969009 | F34: CSE | H34: 85 | I34: 79 | J34: =IFNA(VLOOKUP(D34,'L3'!$1:$2060,2,False),0) -> 61 | K34: =VLOOKUP(D34,'L4'!$1:$2059,2,FALSE) -> 70 | L34: =VLOOKUP(D34,'A1 RETEST 5 DEC'!$1:$2096,2,FALSE) -> 68 | M34: =VLOOKUP(D34,'A2 RETEST 4 DEC'!$1:$2096,2,FALSE) -> 53 | N34: 0 | P34: =IFNA(VLOOKUP(D34,'S1'!$1:$1325,2,False),0) -> 50 | Q34: =IFNA(vlookup(D34,'S2'!A30:B1232,2,False),0) -> 68 | R34: =ifna(vlookup(D34,'S3'!$1:$1311,2,False),0) -> 50 | T34: 10 | U34: 18 | V34: 64 | AA34: 50 | AB34: 75 | AC34: 0 | AD34: 4 | AE34: 10 | AG34: 0 | AK34: =IF(H34>=$H$4, IF(I34>=$I$4, IF(J34>=$J$4, IF(K34>=$K$4, 4, 3), 2), 1), 0) -> 2 | AL34: =IF(L34>=$L$4, IF(M34>=$M$4, IF(N34>=$N$4, IF(O34>=$O$4, 4, 3), 2), 1), 0) -> 2 | AM34: =IF(AND(U34>=$U$4, W34>=$W$4, Y34>=$Y$4, Z34<>"", Z34>=$Z$4), 5, IF(AND(U34>=$U$4, W34>=$W$4, Y34>=$Y$4), 4, IF(AND(U34>=$U$4, W34>=$W$4), 3, IF(AND(T34>=$T$4, U34>=$U$4), 2, 0 ) ) ) ) -> 2 | AN34: =IF(AB34>=$AB$4, IF(OR(AC34>=$AC$4, AD34>=$AD$4), IF(AND(AE34>=$AE$4, AF34>=$AF$4, OR(AG34>=$AG$4, AH34>=$AH$4)), "4", IF(OR(AE34>=$AE$4, AF34>=$AF$4), "3.5", "3")), "2"), "0") -> 2 | AO34: =IF(P34>=$P$4, IF(Q34>=$Q$4, IF(R34>=$R$4, IF(S34>=$S$4,4,3), 2), 1), 0) -> 3
A35: 30 | B35: anku23cs@cmrit.ac.in | C35: ANANYA KULKARNI | D35: =VLOOKUP(B35,USN!$1:$1088,2,FALSE) -> 1CR23CS031 | E35: 9148696928 | F35: CSE | H35: 88 | I35: 94 | J35: =IFNA(VLOOKUP(D35,'L3'!$1:$2060,2,False),0) -> 89 | K35: =VLOOKUP(D35,'L4'!$1:$2059,2,FALSE) -> 78 | L35: =VLOOKUP(D35,'A1 RETEST 5 DEC'!$1:$2096,2,FALSE) -> 44 | M35: =VLOOKUP(D35,'A2 RETEST 4 DEC'!$1:$2096,2,FALSE) -> 14 | N35: 12 | P35: =IFNA(VLOOKUP(D35,'S1'!$1:$1325,2,False),0) -> 76 | Q35: =IFNA(vlookup(D35,'S2'!A31:B1233,2,False),0) -> 73 | R35: =ifna(vlookup(D35,'S3'!$1:$1311,2,False),0) -> 0 | T35: 12 | U35: 19 | W35: 52 | X35: 50 | AA35: 70 | AB35: 92.5 | AC35: 15 | AD35: 0 | AE35: 10 | AG35: 5 | AK35: =IF(H35>=$H$4, IF(I35>=$I$4, IF(J35>=$J$4, IF(K35>=$K$4, 4, 3), 2), 1), 0) -> 4 | AL35: =IF(L35>=$L$4, IF(M35>=$M$4, IF(N35>=$N$4, IF(O35>=$O$4, 4, 3), 2), 1), 0) -> 0 | AM35: =IF(AND(U35>=$U$4, W35>=$W$4, Y35>=$Y$4, Z35<>"", Z35>=$Z$4), 5, IF(AND(U35>=$U$4, W35>=$W$4, Y35>=$Y$4), 4, IF(AND(U35>=$U$4, W35>=$W$4), 3, IF(AND(T35>=$T$4, U35>=$U$4), 2, 0 ) ) ) ) -> 3 | AN35: =IF(AB35>=$AB$4, IF(OR(AC35>=$AC$4, AD35>=$AD$4), IF(AND(AE35>=$AE$4, AF35>=$AF$4, OR(AG35>=$AG$4, AH35>=$AH$4)), "4", IF(OR(AE35>=$AE$4, AF35>=$AF$4), "3.5", "3")), "2"), "0") -> 2 | AO35: =IF(P35>=$P$4, IF(Q35>=$Q$4, IF(R35>=$R$4, IF(S35>=$S$4,4,3), 2), 1), 0) -> 2
A36: 31 | B36: anvi23cs@cmrit.ac.in | C36: ANANYA VIJETHA | D36: =VLOOKUP(B36,USN!$1:$1088,2,FALSE) -> 1CR23CS032 | E36: 9986266664 | F36: CSE | H36: 88 | I36: 89 | J36: =IFNA(VLOOKUP(D36,'L3'!$1:$2060,2,False),0) -> 80 | K36: =VLOOKUP(D36,'L4'!$1:$2059,2,FALSE) -> 82 | L36: =VLOOKUP(D36,'A1 RETEST 5 DEC'!$1:$2096,2,FALSE) -> 57 | M36: =VLOOKUP(D36,'A2 RETEST 4 DEC'!$1:$2096,2,FALSE) -> 17 | N36: 50 | P36: =IFNA(VLOOKUP(D36,'S1'!$1:$1325,2,False),0) -> 74 | Q36: =IFNA(vlookup(D36,'S2'!A32:B1234,2,False),0) -> 90 | R36: =ifna(vlookup(D36,'S3'!$1:$1311,2,False),0) -> 96 | T36: 14 | U36: 18 | V36: 52 | W36: 44 | X36: 84 | AA36: 90 | AB36: 100 | AC36: 83.5 | AD36: 100 | AE36: 88 | AG36: 61 | AK36: =IF(H36>=$H$4, IF(I36>=$I$4, IF(J36>=$J$4, IF(K36>=$K$4, 4, 3), 2), 1), 0) -> 4 | AL36: =IF(L36>=$L$4, IF(M36>=$M$4, IF(N36>=$N$4, IF(O36>=$O$4, 4, 3), 2), 1), 0) -> 1 | AM36: =IF(AND(U36>=$U$4, W36>=$W$4, Y36>=$Y$4, Z36<>"", Z36>=$Z$4), 5, IF(AND(U36>=$U$4, W36>=$W$4, Y36>=$Y$4), 4, IF(AND(U36>=$U$4, W36>=$W$4), 3, IF(AND(T36>=$T$4, U36>=$U$4), 2, 0 ) ) ) ) -> 2 | AN36: =IF(AB36>=$AB$4, IF(OR(AC36>=$AC$4, AD36>=$AD$4), IF(AND(AE36>=$AE$4, AF36>=$AF$4, OR(AG36>=$AG$4, AH36>=$AH$4)), "4", IF(OR(AE36>=$AE$4, AF36>=$AF$4), "3.5", "3")), "2"), "0") -> 3.5 | AO36: =IF(P36>=$P$4, IF(Q36>=$Q$4, IF(R36>=$R$4, IF(S36>=$S$4,4,3), 2), 1), 0) -> 3
A37: 32 | B37: anch23cs@cmrit.ac.in | C37: ANASUYA CHAKRABORTY | D37: =VLOOKUP(B37,USN!$1:$1088,2,FALSE) -> 1CR23CS033 | E37: 6362495768 | F37: CSE | H37: 80 | I37: 85 | J37: =IFNA(VLOOKUP(D37,'L3'!$1:$2060,2,False),0) -> 83 | K37: =VLOOKUP(D37,'L4'!$1:$2059,2,FALSE) -> 78 | L37: =VLOOKUP(D37,'A1 RETEST 5 DEC'!$1:$2096,2,FALSE) -> 52 | M37: =VLOOKUP(D37,'A2 RETEST 4 DEC'!$1:$2096,2,FALSE) -> 23 | N37: 27 | P37: =IFNA(VLOOKUP(D37,'S1'!$1:$1325,2,False),0) -> 87 | Q37: =IFNA(vlookup(D37,'S2'!A33:B1235,2,False),0) -> 90 | R37: =ifna(vlookup(D37,'S3'!$1:$1311,2,False),0) -> 96 | T37: 13 | U37: 20 | V37: 75 | W37: 32 | X37: 82 | AA37: 85 | AB37: 90 | AC37: 84 | AD37: 100 | AE37: 71 | AG37: 70 | AK37: =IF(H37>=$H$4, IF(I37>=$I$4, IF(J37>=$J$4, IF(K37>=$K$4, 4, 3), 2), 1), 0) -> 4 | AL37: =IF(L37>=$L$4, IF(M37>=$M$4, IF(N37>=$N$4, IF(O37>=$O$4, 4, 3), 2), 1), 0) -> 1 | AM37: =IF(AND(U37>=$U$4, W37>=$W$4, Y37>=$Y$4, Z37<>"", Z37>=$Z$4), 5, IF(AND(U37>=$U$4, W37>=$W$4, Y37>=$Y$4), 4, IF(AND(U37>=$U$4, W37>=$W$4), 3, IF(AND(T37>=$T$4, U37>=$U$4), 2, 0 ) ) ) ) -> 2 | AN37: =IF(AB37>=$AB$4, IF(OR(AC37>=$AC$4, AD37>=$AD$4), IF(AND(AE37>=$AE$4, AF37>=$AF$4, OR(AG37>=$AG$4, AH37>=$AH$4)), "4", IF(OR(AE37>=$AE$4, AF37>=$AF$4), "3.5", "3")), "2"), "0") -> 3.5 | AO37: =IF(P37>=$P$4, IF(Q37>=$Q$4, IF(R37>=$R$4, IF(S37>=$S$4,4,3), 2), 1), 0) -> 3
A38: 33 | B38: anho23cs@cmrit.ac.in | C38: ANIRUDDHA S HOLLA | D38: =VLOOKUP(B38,USN!$1:$1088,2,FALSE) -> 1CR23CS034 | E38: 7619415579 | F38: CSE | H38: 86 | I38: 86 | J38: =IFNA(VLOOKUP(D38,'L3'!$1:$2060,2,False),0) -> 80 | K38: =VLOOKUP(D38,'L4'!$1:$2059,2,FALSE) -> 70 | L38: =VLOOKUP(D38,'A1 RETEST 5 DEC'!$1:$2096,2,FALSE) -> 62 | M38: =VLOOKUP(D38,'A2 RETEST 4 DEC'!$1:$2096,2,FALSE) -> 50 | N38: 61 | P38: =IFNA(VLOOKUP(D38,'S1'!$1:$1325,2,False),0) -> 50 | Q38: =IFNA(vlookup(D38,'S2'!A34:B1236,2,False),0) -> 65 | R38: =ifna(vlookup(D38,'S3'!$1:$1311,2,False),0) -> 75 | T38: 15 | U38: 18 | V38: 56 | W38: 44 | X38: 84 | AA38: 82 | AB38: 96.25 | AC38: 100 | AD38: 100 | AE38: 70 | AG38: 27 | AK38: =IF(H38>=$H$4, IF(I38>=$I$4, IF(J38>=$J$4, IF(K38>=$K$4, 4, 3), 2), 1), 0) -> 4 | AL38: =IF(L38>=$L$4, IF(M38>=$M$4, IF(N38>=$N$4, IF(O38>=$O$4, 4, 3), 2), 1), 0) -> 3 | AM38: =IF(AND(U38>=$U$4, W38>=$W$4, Y38>=$Y$4, Z38<>"", Z38>=$Z$4), 5, IF(AND(U38>=$U$4, W38>=$W$4, Y38>=$Y$4), 4, IF(AND(U38>=$U$4, W38>=$W$4), 3, IF(AND(T38>=$T$4, U38>=$U$4), 2, 0 ) ) ) ) -> 2 | AN38: =IF(AB38>=$AB$4, IF(OR(AC38>=$AC$4, AD38>=$AD$4), IF(AND(AE38>=$AE$4, AF38>=$AF$4, OR(AG38>=$AG$4, AH38>=$AH$4)), "4", IF(OR(AE38>=$AE$4, AF38>=$AF$4), "3.5", "3")), "2"), "0") -> 3.5 | AO38: =IF(P38>=$P$4, IF(Q38>=$Q$4, IF(R38>=$R$4, IF(S38>=$S$4,4,3), 2), 1), 0) -> 3
A39: 34 | B39: ankr23cs@cmrit.ac.in | C39: Ankitha K R | D39: =VLOOKUP(B39,USN!$1:$1088,2,FALSE) -> 1CR23CS035 | E39: 8792061225 | F39: CSE | H39: 87 | I39: 85 | J39: =IFNA(VLOOKUP(D39,'L3'!$1:$2060,2,False),0) -> 70 | K39: =VLOOKUP(D39,'L4'!$1:$2059,2,FALSE) -> 70 | L39: =VLOOKUP(D39,'A1 RETEST 5 DEC'!$1:$2096,2,FALSE) -> 50 | M39: =VLOOKUP(D39,'A2 RETEST 4 DEC'!$1:$2096,2,FALSE) -> 17 | N39: 50 | P39: =IFNA(VLOOKUP(D39,'S1'!$1:$1325,2,False),0) -> 76 | Q39: =IFNA(vlookup(D39,'S2'!A35:B1237,2,False),0) -> 66 | R39: =ifna(vlookup(D39,'S3'!$1:$1311,2,False),0) -> 85 | T39: 10 | U39: 23 | V39: 64 | W39: 52 | X39: 86 | AA39: 80 | AB39: 91.25 | AC39: 60 | AD39: 100 | AE39: 70 | AG39: 71 | AK39: =IF(H39>=$H$4, IF(I39>=$I$4, IF(J39>=$J$4, IF(K39>=$K$4, 4, 3), 2), 1), 0) -> 4 | AL39: =IF(L39>=$L$4, IF(M39>=$M$4, IF(N39>=$N$4, IF(O39>=$O$4, 4, 3), 2), 1), 0) -> 1 | AM39: =IF(AND(U39>=$U$4, W39>=$W$4, Y39>=$Y$4, Z39<>"", Z39>=$Z$4), 5, IF(AND(U39>=$U$4, W39>=$W$4, Y39>=$Y$4), 4, IF(AND(U39>=$U$4, W39>=$W$4), 3, IF(AND(T39>=$T$4, U39>=$U$4), 2, 0 ) ) ) ) -> 3 | AN39: =IF(AB39>=$AB$4, IF(OR(AC39>=$AC$4, AD39>=$AD$4), IF(AND(AE39>=$AE$4, AF39>=$AF$4, OR(AG39>=$AG$4, AH39>=$AH$4)), "4", IF(OR(AE39>=$AE$4, AF39>=$AF$4), "3.5", "3")), "2"), "0") -> 3.5 | AO39: =IF(P39>=$P$4, IF(Q39>=$Q$4, IF(R39>=$R$4, IF(S39>=$S$4,4,3), 2), 1), 0) -> 3
A40: 35 | B40: ansu23cs@cmrit.ac.in | C40: ANSHIKA SUPRIYA | D40: =VLOOKUP(B40,USN!$1:$1088,2,FALSE) -> 1CR23CS036 | E40: 8210060969 | F40: CSE | H40: 86 | I40: 88 | J40: =IFNA(VLOOKUP(D40,'L3'!$1:$2060,2,False),0) -> 70 | K40: =VLOOKUP(D40,'L4'!$1:$2059,2,FALSE) -> 70 | L40: =VLOOKUP(D40,'A1 RETEST 5 DEC'!$1:$2096,2,FALSE) -> 83 | M40: =VLOOKUP(D40,'A2 RETEST 4 DEC'!$1:$2096,2,FALSE) -> 50 | N40: 53 | P40: =IFNA(VLOOKUP(D40,'S1'!$1:$1325,2,False),0) -> 82 | Q40: =IFNA(vlookup(D40,'S2'!A36:B1238,2,False),0) -> 63 | R40: =ifna(vlookup(D40,'S3'!$1:$1311,2,False),0) -> 88 | T40: 11 | U40: 19 | V40: 72 | W40: 52 | X40: 86 | AA40: 100 | AB40: 100 | AC40: 84 | AD40: 60 | AE40: 80 | AG40: 70 | AK40: =IF(H40>=$H$4, IF(I40>=$I$4, IF(J40>=$J$4, IF(K40>=$K$4, 4, 3), 2), 1), 0) -> 4 | AL40: =IF(L40>=$L$4, IF(M40>=$M$4, IF(N40>=$N$4, IF(O40>=$O$4, 4, 3), 2), 1), 0) -> 3 | AM40: =IF(AND(U40>=$U$4, W40>=$W$4, Y40>=$Y$4, Z40<>"", Z40>=$Z$4), 5, IF(AND(U40>=$U$4, W40>=$W$4, Y40>=$Y$4), 4, IF(AND(U40>=$U$4, W40>=$W$4), 3, IF(AND(T40>=$T$4, U40>=$U$4), 2, 0 ) ) ) ) -> 3 | AN40: =IF(AB40>=$AB$4, IF(OR(AC40>=$AC$4, AD40>=$AD$4), IF(AND(AE40>=$AE$4, AF40>=$AF$4, OR(AG40>=$AG$4, AH40>=$AH$4)), "4", IF(OR(AE40>=$AE$4, AF40>=$AF$4), "3.5", "3")), "2"), "0") -> 3.5 | AO40: =IF(P40>=$P$4, IF(Q40>=$Q$4, IF(R40>=$R$4, IF(S40>=$S$4,4,3), 2), 1), 0) -> 3
...

Sheet A3
A1: E mail ID | B1: Name | C1: USN Number | D1: IAT 1 (40) | E1: IAT 2(50) | F1: Total (90) | G1: Attendance % | H1: Attendance Marks(10) | I1: Final Marks
A2: mohm22cs@cmrit.ac.in | B2: M Mohan | C2: 1CR22CS094 | D2: 0 | E2: 0 | F2: 0 | G2: 0 | H2: 0 | I2: 0
A3: nadi22cs@cmrit.ac.in | B3: Naman Didwania | C3: 1CR22CS116 | D3: 0 | E3: 0 | F3: 0 | G3: 0 | H3: 0 | I3: 0
A4: sulkh22cs@cmrit.ac.in | B4: Sulaiman Khan | C4: 1CR22CS194 | D4: 0 | E4: 0 | F4: 0 | G4: 3.4482759 | H4: 0 | I4: 0
A5: vave22cs@cmrit.ac.in | B5: Varun Venugopal | C5: 1CR22CS209 | D5: 0 | E5: 0 | F5: 0 | G5: 27.586207 | H5: 0 | I5: 0
A6: hada22ece@cmrit.ac.in | B6: HARI OM KUMAR DAS | C6: 1CR22EC082 | D6: 11.75 | E6: 7.5 | F6: 19.25 | G6: 76.923077 | H6: 7 | I6: 26.25
A7: hada22ece@cmrit.ac.in | B7: Mohammed Shoaib | C7: 1CR22EC144 | D7: 0 | E7: 0 | F7: 0 | G7: 3.8461538 | H7: 0 | I7: 0
A8: ara23ainds@cmrit.ac.in | B8: A RAHHUL NANDHAN | C8: 1CR23AD001 | D8: 35 | E8: 19.5 | F8: 54.5 | G8: 0 | H8: 0 | I8: 54.5
A9: aara23ainds@cmrit.ac.in | B9: Aayush Rasaily | C9: 1CR23AD002 | D9: 30 | E9: 24.5 | F9: 54.5 | G9: 60.869565 | H9: 0 | I9: 54.5
A10: abas23ainds@cmrit.ac.in | B10: ABHAYASURYA A S | C10: 1CR23AD003 | D10: 23.75 | E10: 23.5 | F10: 47.25 | G10: 78.26087 | H10: 7 | I10: 54.25
A11: abku23ainds@cmrit.ac.in | B11: ABHINASH KUMAR | C11: 1CR23AD004 | D11: 25 | E11: 39.5 | F11: 64.5 | G11: 26.086957 | H11: 0 | I11: 64.5
A12: adi23ainds@cmrit.ac.in | B12: ADITY SINHA | C12: 1CR23AD005 | D12: 21.5 | E12: 22.25 | F12: 43.75 | G12: 86.956522 | H12: 9 | I12: 52.75
A13: adbh23ainds@cmrit.ac.in | B13: Aditya Bhattarai | C13: 1CR23AD006 | D13: 22.75 | E13: 0 | F13: 22.75 | G13: 30.434783 | H13: 0 | I13: 22.75
